Workbook
Name \e: #REF!
Name __________JM1: #REF!
Name __________JM1_1: #REF!
Name __________JM1_10: #REF!
Name __________JM1_6: #REF!
Name __________JM1_8: #REF!
Name __________JM1_9: #REF!
Name __________JM2: #REF!
Name __________JM2_1: #REF!
Name __________JM2_10: #REF!
Name __________JM2_6: #REF!
Name __________JM2_8: #REF!
Name __________JM2_9: #REF!
Name __________JM3: #REF!
Name __________JM3_1: #REF!
Name __________JM3_10: #REF!
Name __________JM3_6: #REF!
Name __________JM3_8: #REF!
Name __________JM3_9: #REF!
Name __________JM4: #REF!
Name __________JM4_1: #REF!
Name __________JM4_10: #REF!
Name __________JM4_6: #REF!
Name __________JM4_8: #REF!
Name __________JM4_9: #REF!
Name __________JM5: #REF!
Name __________JM5_1: #REF!
Name __________JM5_10: #REF!
Name __________JM5_6: #REF!
Name __________JM5_8: #REF!
Name __________JM5_9: #REF!
Name __________JM6: #REF!
Name __________JM6_1: #REF!
Name __________JM6_10: #REF!
Name __________JM6_6: #REF!
Name __________JM6_8: #REF!
Name __________JM6_9: #REF!
Name __________PM1: #REF!
Name __________PM1_1: #REF!
Name __________PM1_10: #REF!
Name __________PM1_6: #REF!
Name __________PM1_8: #REF!
Name __________PM1_9: #REF!
Name __________PM2: #REF!
Name __________PM2_1: #REF!
Name __________PM2_10: #REF!
Name __________PM2_6: #REF!
Name __________PM2_8: #REF!
Name __________PM2_9: #REF!
Name __________PM3: #REF!
Name __________PM3_1: #REF!
Name __________PM3_10: #REF!
Name __________PM3_6: #REF!
Name __________PM3_8: #REF!
Name __________PM3_9: #REF!
Name __________PM4: #REF!
Name __________PM4_1: #REF!
Name __________PM4_10: #REF!
Name __________PM4_6: #REF!
Name __________PM4_8: #REF!

Sheet CONFIG
B1: INFORMAR MEDIÇÃO | I1: vigência
B2: 4
N3: =N7/N6 -> 0.22988506 | O3: ="PRAZO DE VIGÊNCIA - 0"&DAY(O6)&"/"&MONTH(O6)&"/"&YEAR(O6) -> PRAZO DE VIGÊNCIA - 04/12/2028
N4: =1-N3 -> 0.77011494 | O4: ="VIGÊNCIA DECORRIDA - "&N7&" DIAS" -> VIGÊNCIA DECORRIDA - 280 DIAS
O5: ="VIGÊNCIA RESTANTE - "&N6-N7&" DIAS" -> VIGÊNCIA RESTANTE - 938 DIAS
I6: PRAZO DE VIGÊNCIA | L6: ='RESUM.'!I24 -> 45873 | N6: =O6-L6 -> 1218 | O6: ='RESUM.'!AC24 -> 47091
B7: EAP ORÇAMENTO | I7: VIGÊNCIA DECORRIDA | N7: =O7-L6 -> 280 | O7: =TODAY() -> 46153
A8: 1 | B8: SERVIÇOS PRELIMINARES | C8: =VLOOKUP(A8,'EAP DE MEDIÇÃO'!$B$12:$DM$268,116,0) -> 0.99046778 | D8: =VLOOKUP(A8,'EAP DE MEDIÇÃO'!B12:DM268,114,0) -> 678310.22
A9: 2 | B9: ADMINISTRAÇÃO DA OBRA | C9: =VLOOKUP(A9,'EAP DE MEDIÇÃO'!$B$12:$DM$268,116,0) -> 0.082108315 | D9: =VLOOKUP(A9,'EAP DE MEDIÇÃO'!B13:DM269,114,0) -> 191575.6
A10: 3 | B10: FUNDAÇÕES E ESTRUTURAS | C10: =VLOOKUP(A10,'EAP DE MEDIÇÃO'!$B$12:$DM$268,116,0) -> 0.24320415 | D10: =VLOOKUP(A10,'EAP DE MEDIÇÃO'!B14:DM270,114,0) -> 1475681.9 | I10: execução
A11: 4 | B11: ARQUITETURA E ELEMENTOS DE URBANISMO | C11: =VLOOKUP(A11,'EAP DE MEDIÇÃO'!$B$12:$DM$268,116,0) -> 0 | D11: =VLOOKUP(A11,'EAP DE MEDIÇÃO'!B15:DM271,114,0) -> 0 | N11: =N15/N14 -> 0.13868613 | O11: ="PRAZO DE EXECUÇÃO - "&DAY(O14)&"/"&MONTH(O14)&"/"&YEAR(O14) -> PRAZO DE EXECUÇÃO - 10/12/2028
A12: 5 | B12: INSTALAÇÕES HIDROSSANITARIAS | C12: =VLOOKUP(A12,'EAP DE MEDIÇÃO'!$B$12:$DM$268,116,0) -> 0 | D12: =VLOOKUP(A12,'EAP DE MEDIÇÃO'!B16:DM272,114,0) -> 0 | N12: =1-N11 -> 0.86131387 | O12: ="EXECUÇÃO DECORRIDA - "&N15&" DIAS" -> EXECUÇÃO DECORRIDA - 152 DIAS
A13: 6 | B13: INSTALAÇOES ELETRICAS E ELETRONICAS | C13: =VLOOKUP(A13,'EAP DE MEDIÇÃO'!$B$12:$DM$268,116,0) -> 0 | D13: =VLOOKUP(A13,'EAP DE MEDIÇÃO'!B17:DM273,114,0) -> 0 | O13: ="EXECUÇÃO RESTANTE - "&N14-N15&" DIAS" -> EXECUÇÃO RESTANTE - 944 DIAS
A14: 7 | B14: EQUIPAMENTOS - INSTALAÇÕES MECÂNICAS E UTILIDADES | C14: =VLOOKUP(A14,'EAP DE MEDIÇÃO'!$B$12:$DM$268,116,0) -> 0 | D14: =VLOOKUP(A14,'EAP DE MEDIÇÃO'!B18:DM274,114,0) -> 0 | I14: PRAZO DE EXECUÇÃO | L14: ='RESUM.'!I28 -> 46001 | N14: =O14-L14 -> 1096 | O14: ='RESUM.'!J29 -> 47097
A15: 8 | B15: PREVENÇÃO DE COMBATE A INCENDIO | C15: =VLOOKUP(A15,'EAP DE MEDIÇÃO'!$B$12:$DM$268,116,0) -> 0 | D15: =VLOOKUP(A15,'EAP DE MEDIÇÃO'!B19:DM275,114,0) -> 0 | I15: EXECUÇÃO DECORRIDA | N15: =O15-L14 -> 152 | O15: =TODAY() -> 46153
A16: 9 | B16: SERVIÇOS COMPLEMENTARES | C16: =VLOOKUP(A16,'EAP DE MEDIÇÃO'!$B$12:$DM$268,116,0) -> 0 | D16: =VLOOKUP(A16,'EAP DE MEDIÇÃO'!B20:DM276,114,0) -> 0
A17: 10 | B17: USINA FOTOVOLTAICA | C17: =VLOOKUP(A17,'EAP DE MEDIÇÃO'!$B$12:$DM$268,116,0) -> 0 | D17: =VLOOKUP(A17,'EAP DE MEDIÇÃO'!B21:DM277,114,0) -> 0
B19: 1 | I19: avanço físico da obra
B20: 2
B21: 3 | I21: AVANÇ. REAL. | K21: AVANÇ. PLAN.
B22: 4 | I22: =VLOOKUP(B2,'RESUM.'!$D$52:$R$87,14,0) -> 0.046795872 | K22: =HLOOKUP(B2,'CRONOGRAMA DE METAS'!$G$8:$DJ$272,265,0) -> 0.033904196
B23: 5 | I23: =1-K22 -> 0.9660958 | K23: =1-I22 -> 0.95320413
B24: 6
B25: 7
B26: 8 | I26: idp
B27: 9 | J27: IDP | M27: =IF((VLOOKUP(CONFIG!B2,'RESUM.'!$D$52:$AD$87,24,0))/(HLOOKUP(B2,'CRONOGRAMA DE METAS'!$G$8:$DJ$273,264,0))<=2,(VLOOKUP(CONFIG!B2,'RESUM.'!$D$52:$AD$87,24,0))/(HLOOKUP(B2,'CRONOGRAMA DE METAS'!$G$8:$DJ$273,264,0)),"2,00") -> 1
B28: 10 | P28: =IF(M27<0.95,"OBRA ATRASADA",IF(AND(M27>=0.95,M27<=1.05),"OBRA NO PRAZO","OBRA ADIANTADA")) -> OBRA NO PRAZO
B29: 11 | I29: % | J29: SETA | M29: OCULTA
B30: 12 | I30: =(M27/2)-(0.5/100) -> 0.495 | J30: 0.01 | M30: =2-I30-J30 -> 1.495
B31: 13
B32: 14
B33: 15 | I33: tendência de término
B34: 16 | I34: duração da obra (d) | L34: =('RESUM.'!$J$29-'RESUM.'!$I$28)-'RESUM.'!U28 -> 1096 | P34: =IF('RESUM.'!R29="CONCLUÍDA","OBRA CONCLUÍDA","TENDÊNCIA DE DURAÇÃO DA OBRA - "&L35&" DIAS") -> TENDÊNCIA DE DURAÇÃO DA OBRA - 1096 DIAS
B35: 17 | I35: nova duração (d) | L35: =ROUNDDOWN(L34/M27,0) -> 1096 | N35: duração / idp | P35: =IF('RESUM.'!R29="CONCLUÍDA","-","TENDÊNCIA DE TÉRMINO DA OBRA - "&DAY(L37)&"/"&MONTH(L37)&"/"&YEAR(L37)) -> TENDÊNCIA DE TÉRMINO DA OBRA - 10/12/2028
B36: 18 | I36: nova duração (MêS) | L36: =ROUND(L35/30,2) -> 36.53
B37: 19 | I37: nova data de término | L37: ='RESUM.'!I28+'RESUM.'!U28+L35 -> 47097
B38: 20
B39: 21
B40: 22
B41: 23
...

Sheet CAPA MEDIÇÃO
A17: =CONFIG!B2 -> 4
A18: =VLOOKUP(CONFIG!B2,'RESUM.'!$D$52:$AD$90,5,0) -> 46082 | E18: A | F18: =VLOOKUP(CONFIG!B2,'RESUM.'!$D$52:$AD$90,8,0) -> 46112
A22: ='RESUM.'!H9 -> CONSTRUÇÃO DA NOVA SEDE DA JUSTIÇA FEDERAL EM JUAZEIRO DO NORTE/CE
T25: 1
A28: ='RESUM.'!D11 -> Nº DO CONTRATO: | F28: ='RESUM.'!H11 -> 25/2025 | T28: 1
T29: 1

Sheet CARTA DE ENTREGA
L2: =DAY('CAPA MEDIÇÃO'!F18)&"/"&MONTH('CAPA MEDIÇÃO'!F18)&"/"&YEAR('CAPA MEDIÇÃO'!F18) -> 31/3/2026
A6: À Justiça federal de primeira instância no estado do ceará
A8: Ref.: | B8: ='RESUM.'!H11&" - "&'RESUM.'!H9 -> 25/2025 - CONSTRUÇÃO DA NOVA SEDE DA JUSTIÇA FEDERAL EM JUAZEIRO DO NORTE/CE
A10: Empresa: | B10: ='RESUM.'!H13&" - "&'RESUM.'!Y13 -> CONSÓRCIO JUAZEIRO DO NORTE - 62.009.288/0001-12
A12: Assunto: | B12: ='CAPA MEDIÇÃO'!A17 -> 4
A14: Senhor(a) Coordenador(a),
A16: ="Encaminhamos em anexo a medição de nº "&B12&" do contrato em referência, relativa ao período de "&DAY('CAPA MEDIÇÃO'!A18)&"/"&MONTH('CAPA MEDIÇÃO'!A18)&"/"&YEAR('CAPA MEDIÇÃO'!A18)&" a "&DAY('CAPA MEDIÇÃO'!F18)&"/"&MONTH('CAPA MEDIÇÃO'!F18)&"/"&YEAR('CAPA MEDIÇÃO'!F18)&", no valor de "&TEXT(HLOOKUP(B12,CONFIG!$N$46:$AW$50,5,0),"R$ #.##0,00")&"." -> Encaminhamos em anexo a medição de nº 4 do contrato em referência, relativa ao período de 1/3/2026 a 31/3/2026, no valor de R$ 968.532,67.
T25: 1
H26: =DATEVALUE(L2) -> 46112
A28: Atenciosamente, | T28: 1
T29: 1
A32: =B10 -> CONSÓRCIO JUAZEIRO DO NORTE - 62.009.288/0001-12

Sheet RESUM.
D4: JUSTIÇA FEDERAL DE PRIMEIRA INSTÂNCIA NO ESTADO DO CEARÁ
D6: RELATÓRIO DE CONTROLE DO CONTRATO
D8: INFORMAÇÕES DO CONTRATO
D9: OBJETO: | H9: CONSTRUÇÃO DA NOVA SEDE DA JUSTIÇA FEDERAL EM JUAZEIRO DO NORTE/CE
D10: ENDEREÇO: | H10: RUAS JOSÉ GERALDO DA CRUZ (L) COM A RUA PRESIDENTE MÉDICI (O), NA RUA MANOEL PIRES (N) COM A RUA FREI DAMIÃO (S), BAIRRO LAGOA SECA NO MUNICÍPIO DE JUAZEIRO DO NORTE-CE
D11: Nº DO CONTRATO: | H11: 25/2025 | N11: CONCORRÊNCIA PÚBLICA: | R11: 90001/2025 | X11: CNO DA OBRA: | AB11: 90.025.93927/72
D12: SECRETARIA GESTORA:
D13: EMPRESA CONTRATADA: | H13: CONSÓRCIO JUAZEIRO DO NORTE | V13: CNPJ.: | Y13: 62.009.288/0001-12
D14: RECURSO: | P14: ÓRGÃO CONCEDENTE: | Y14: Nº CONVÊNIO: | AB14: PT
D15: GESTOR DO CONTRATO: | M15: FISCAL DO CONTRATO: | T15: FISCAL DA OBRA: | AB15: ENG. CIVIL
AB16: ENG. ELETRICISTA
M17: FISCAL RESERVA: | T17: FISCAL RESERVA: | AB17: ENG. CIVIL
D19: VALOR DO CONTRATO
D20: VALOR INICIAL DO CONTRATO: | H20: 28566749 | K20: VALOR DE REPASSE: | S20: =P20/H20 -> 0 | U20: VALOR DE CONTRAPARTIDA: | AC20: =Z20/H20 -> 0
D21: VALOR ATUAL DO CONTRATO: | H21: =H20+SUM(Y37:AA47) -> 28566749 | K21: VALOR DE REPASSE: | S21: =P21/H21 -> 0 | U21: VALOR DE CONTRAPARTIDA: | AC21: =Z21/H21 -> 0
D23: PRAZO DE VIGÊNCIA DO CONTRATO
D24: DATA DA ASSINATURA DO CONTRATO: | I24: 45873 | K24: PERÍODO DE VIGÊNCIA DO CONTRATO: | O24: 40 | P24: MESES | Q24: PERÍODO DE VIGÊNCIA ADITIVADO AO CONTRATO: | U24: 0 | V24: MESES | W24: DATA DO TÉRMINO DA VIGÊNGIA DO CONTRATO: | AC24: =EDATE(I24,O24+U24) -> 47091
D25: SITUAÇÃO DO CONTRATO: | M25: VIGENTE | S25: PRAZO RESTANTE DE VIGÊNCIA DO CONTRATO (DIAS): | AC25: =CONFIG!N6-CONFIG!N7 -> 938
D27: PRAZO DE EXECUÇÃO DO CONTRATO
D28: DATA DA ORDEM DE SERVIÇO: | I28: 46001 | K28: PRAZO DE EXECUÇÃO : | O28: 36 | P28: MESES | Q28: TOTAL DE DIAS PARALISADOS: | U28: =SUM(U33:W33) -> 0 | V28: PERÍODO DE EXECUÇÃO ADITIVADO AO CONTRATO: | AD28: MESES
D29: DATA DO TÉRMINO DA EXECUÇÃO DA OBRA: | J29: =EDATE(I28,O28+AC28)+U28 -> 47097 | M29: SITUAÇÃO DA OBRA: | R29: NÃO INICIADA | U29: PRAZO RESTANTE DE EXECUÇÃO DO CONTRATO (DIAS): | AC29: =CONFIG!N14-CONFIG!N15 -> 944
D31: PARALISAÇÕES
D32: PARALISAÇÕES | G32: DATA DO INÍCIO DA PARALISAÇÃO DA OBRA | N32: DATA DO REINÍCIO DA OBRA | U32: DIAS DE PARALISAÇÃO | X32: MOTIVO
U33: =N33-G33 -> 0
D35: ADITIVOS
D36: DATA | F36: Nº | G36: OBJETO | M36: INÍCIO DO ADITIVO DE PRAZO | P36: TÉRMINO DO ADITIVO DE PRAZO | S36: VALORES ACRÉSCIDOS | V36: VALORES REDUZIDOS | Y36: VALOR DO ADITIVO | AB36: % ADITIVADO
K38: MESES | Y38: =S38-V38 -> 0 | AB38: =ROUND(Y38/$H$20,4) -> 0
K39: MESES | Y39: =S39-V39 -> 0 | AB39: =ROUND(Y39/$H$20,4) -> 0
K40: MESES | Y40: =S40-V40 -> 0 | AB40: =ROUND(Y40/$H$20,4) -> 0
K41: MESES | Y41: =S41-V41 -> 0 | AB41: =ROUND(Y41/$H$20,4) -> 0
Y42: =S42-V42 -> 0 | AB42: =ROUND(Y42/$H$20,4) -> 0
K43: MESES | Y43: =S43-V43 -> 0 | AB43: =ROUND(Y43/$H$20,4) -> 0
K44: MESES | Y44: =S44-V44 -> 0 | AB44: =ROUND(Y44/$H$20,4) -> 0
Y45: =S45-V45 -> 0 | AB45: =ROUND(Y45/$H$20,4) -> 0
Y47: =S47-V47 -> 0 | AB47: =ROUND(Y47/$H$20,4) -> 0
D49: MEDIÇÕES
D50: MEDIÇÃO | F50: DATA DE EMISSÃO | H50: PERÍODO | M50: % EXEC. ATUAL | O50: % EXEC. ANTER. | Q50: % EXEC. ACUM. | S50: VALOR MEDIDO | Y50: VALOR ACUMUL. DA MEDIÇÃO ANTERIOR | AA50: VALOR DA MEDIÇÃO ATUAL ACUMULADO | AC50: VALOR DO SALDO CONTRATUAL
D52: 1 | H52: =HLOOKUP(D52,'CRONOGRAMA DE METAS'!$G$8:$DJ$10,2,0) -> 46001 | J52: a | K52: =HLOOKUP(D52,'CRONOGRAMA DE METAS'!$G$8:$DJ$10,3,0) -> 46022 | M52: =S52/$H$21 -> 0 | O52: =Y52/$H$21 -> 0 | Q52: =AA52/$H$21 -> 0 | S52: =HLOOKUP(D52,'EAP DE MEDIÇÃO'!$G$8:$DJ$272,264,0) -> 0 | Y52: 0 | AA52: =S52+Y52 -> 0 | AC52: =$H$21-AA52 -> 28566749
D53: 2 | H53: =HLOOKUP(D53,'CRONOGRAMA DE METAS'!$G$8:$DJ$10,2,0) -> 46023 | J53: a | K53: =HLOOKUP(D53,'CRONOGRAMA DE METAS'!$G$8:$DJ$10,3,0) -> 46053 | M53: =S53/$H$21 -> 0 | O53: =Y53/$H$21 -> 0 | Q53: =AA53/$H$21 -> 0 | S53: =HLOOKUP(D53,'EAP DE MEDIÇÃO'!$G$8:$DJ$272,264,0) -> 0 | Y53: =AA52 -> 0 | AA53: =S53+Y53 -> 0 | AC53: =$H$21-AA53 -> 28566749
D54: 3 | H54: =HLOOKUP(D54,'CRONOGRAMA DE METAS'!$G$8:$DJ$10,2,0) -> 46054 | J54: a | K54: =HLOOKUP(D54,'CRONOGRAMA DE METAS'!$G$8:$DJ$10,3,0) -> 46081 | M54: =S54/$H$21 -> 0.012891676 | O54: =Y54/$H$21 -> 0 | Q54: =AA54/$H$21 -> 0.012891676 | S54: =HLOOKUP(D54,'EAP DE MEDIÇÃO'!$G$8:$DJ$272,263,0) -> 368273.27 | Y54: =AA53 -> 0 | AA54: =S54+Y54 -> 368273.27 | AC54: =$H$21-AA54 -> 28198476
...

Sheet EAP DE MEDIÇÃO
B1: EAP DE MEDIÇÃO
B3: Contratada: | F3: 62.009.288/0001-12
B4: Consórcio Juazeiro do Norte
B6: Objeto: | F6: 0.088939789
B7: Construção da Nova Sede da Justiça Federal em Juazeiro do Norte/CE | G7: 45992 | J7: 46023 | M7: 46054 | P7: 46082 | S7: 46113 | V7: 46143 | Y7: 46174 | AB7: 46204 | AE7: 46235 | AH7: 46266 | AK7: 46296 | AN7: 46327 | AQ7: 46357 | AT7: 46388 | AW7: 46419 | AZ7: 46447 | BC7: 46478 | BF7: 46508 | BI7: 46539 | BL7: 46569 | BO7: 46600 | BR7: 46631 | BU7: 46661 | BX7: 46692 | CA7: 46722 | CD7: 46753 | CG7: 46784 | CJ7: 46813 | CM7: 46844 | CP7: 46874 | CS7: 46905 | CV7: 46935 | CY7: 46966 | DB7: 46997 | DE7: 47027 | DH7: 47058 | DK7: Acumulado
G8: 1 | J8: 2 | M8: 3 | P8: 4 | S8: 5 | V8: 6 | Y8: 7 | AB8: 8 | AE8: 9 | AH8: 10 | AK8: 11 | AN8: 12 | AQ8: 13 | AT8: 14 | AW8: 15 | AZ8: 16 | BC8: 17 | BF8: 18 | BI8: 19 | BL8: 20 | BO8: 21 | BR8: 22 | BU8: 23 | BX8: 24 | CA8: 25 | CD8: 26 | CG8: 27 | CJ8: 28 | CM8: 29 | CP8: 30 | CS8: 31 | CV8: 32 | CY8: 33 | DB8: 34 | DE8: 35 | DH8: 36 | DK8: RESUMO MEDIÇÕES
G9: 46001 | H9: =G9 -> 46001 | J9: =EOMONTH(J7,-1)+1 -> 46023 | K9: =J9 -> 46023 | M9: =EOMONTH(M7,-1)+1 -> 46054 | N9: =M9 -> 46054
G10: =EOMONTH(G7,0) -> 46022 | H10: =G10 -> 46022 | J10: =EOMONTH(J7,0) -> 46053 | K10: =J10 -> 46053 | M10: =EOMONTH(M7,0) -> 46081 | N10: =M10 -> 46081
B11: ITEM | C11: DESCRIÇÃO | E11: PREÇO TOTAL R$ | G11: Medido (R$) | H11: % do mês | I11: % acumulado | J11: Medido (R$) | K11: % do mês | L11: % acumulado | M11: Medido (R$) | N11: % do mês | O11: % acumulado | P11: Medido (R$) | Q11: % do mês | R11: % acumulado | S11: Medido (R$) | T11: % do mês | U11: % acumulado | V11: Medido (R$) | W11: % do mês | X11: % acumulado | Y11: Medido (R$) | Z11: % do mês | AA11: % acumulado | AB11: Medido (R$) | AC11: % do mês | AD11: % acumulado | AE11: Medido (R$) | AF11: % do mês | AG11: % acumulado | AH11: Medido (R$) | AI11: % do mês | AJ11: % acumulado | AK11: Medido (R$) | AL11: % do mês | AM11: % acumulado | AN11: Medido (R$) | AO11: % do mês | AP11: % acumulado | AQ11: Medido (R$) | AR11: % do mês | AS11: % acumulado | AT11: Medido (R$) | AU11: % do mês | AV11: % acumulado | AW11: Medido (R$) | AX11: % do mês | AY11: % acumulado | AZ11: Medido (R$) | BA11: % do mês | BB11: % acumulado | BC11: Medido (R$) | BD11: % do mês | BE11: % acumulado | BF11: Medido (R$) | BG11: % do mês | BH11: % acumulado | BI11: Medido (R$) | BJ11: % do mês | BK11: % acumulado | BL11: Medido (R$) | BM11: % do mês | BN11: % acumulado | BO11: Medido (R$) | BP11: % do mês | BQ11: % acumulado | BR11: Medido (R$) | BS11: % do mês | BT11: % acumulado | BU11: Medido (R$) | BV11: % do mês | BW11: % acumulado | BX11: Medido (R$) | BY11: % do mês | BZ11: % acumulado | CA11: Medido (R$) | CB11: % do mês | CC11: % acumulado | CD11: Medido (R$) | CE11: % do mês | CF11: % acumulado | CG11: Medido (R$) | CH11: % do mês | CI11: % acumulado | CJ11: Medido (R$) | CK11: % do mês | CL11: % acumulado | CM11: Medido (R$) | CN11: % do mês | CO11: % acumulado | CP11: Medido (R$) | CQ11: % do mês | CR11: % acumulado | CS11: Medido (R$) | CT11: % do mês | CU11: % acumulado | CV11: Medido (R$) | CW11: % do mês | CX11: % acumulado | CY11: Medido (R$) | CZ11: % do mês | DA11: % acumulado | DB11: Medido (R$) | DC11: % do mês | DD11: % acumulado | DE11: Medido (R$) | DF11: % do mês | DG11: % acumulado | DH11: Medido (R$) | DI11: % do mês | DJ11: % acumulado | DK11: Acumulado (R$) | DL11: Saldo a medir (R$) | DM11: % acumulado
B12: 1 | C12: SERVIÇOS PRELIMINARES | E12: =VLOOKUP(B12,'[49]PLANILHA ORCAMENTARIA'!A:G,7,0) -> 684838.25 | G12: =SUMIF($A$13:$A$269,$B$12,G13:G269) -> 0 | H12: =IF(G12="","",G12/$E12) -> 0 | I12: =H12 -> 0 | J12: =SUMIF($A$13:$A$269,$B$12,J13:J269) -> 0 | K12: =IF(J12="","",J12/$E12) -> 0 | L12: =K12+I12 -> 0 | M12: =SUMIF($A$13:$A$269,$B$12,M13:M269) -> 338194.34 | N12: =IF(M12="","",M12/$E12) -> 0.49383097 | O12: =N12+L12 -> 0.49383097 | P12: =SUMIF($A$13:$A$269,$B$12,P13:P269) -> 340115.88 | Q12: =IF(P12="","",P12/$E12) -> 0.4966368 | R12: =Q12+O12 -> 0.99046778 | S12: =SUMIF($A$13:$A$269,$B$12,S13:S269) -> 0 | T12: =IF(S12="","",S12/$E12) -> 0 | U12: =T12+R12 -> 0.99046778 | V12: =SUMIF($A$13:$A$269,$B$12,V13:V269) -> 0 | W12: =IF(V12="","",V12/$E12) -> 0 | X12: =W12+U12 -> 0.99046778 | Y12: =SUMIF($A$13:$A$269,$B$12,Y13:Y269) -> 0 | Z12: =IF(Y12="","",Y12/$E12) -> 0 | AA12: =Z12+X12 -> 0.99046778 | AB12: =SUMIF($A$13:$A$269,$B$12,AB13:AB269) -> 0 | AC12: =IF(AB12="","",AB12/$E12) -> 0 | AD12: =AC12+AA12 -> 0.99046778 | AE12: =SUMIF($A$13:$A$269,$B$12,AE13:AE269) -> 0 | AF12: =IF(AE12="","",AE12/$E12) -> 0 | AG12: =AF12+AD12 -> 0.99046778 | AH12: =SUMIF($A$13:$A$269,$B$12,AH13:AH269) -> 0 | AI12: =IF(AH12="","",AH12/$E12) -> 0 | AJ12: =AI12+AG12 -> 0.99046778 | AK12: =SUMIF($A$13:$A$269,$B$12,AK13:AK269) -> 0 | AL12: =IF(AK12="","",AK12/$E12) -> 0 | AM12: =AL12+AJ12 -> 0.99046778 | AN12: =SUMIF($A$13:$A$269,$B$12,AN13:AN269) -> 0 | AO12: =IF(AN12="","",AN12/$E12) -> 0 | AP12: =AO12+AM12 -> 0.99046778 | AQ12: =SUMIF($A$13:$A$269,$B$12,AQ13:AQ269) -> 0 | AR12: =IF(AQ12="","",AQ12/$E12) -> 0 | AS12: =AR12+AP12 -> 0.99046778 | AT12: =SUMIF($A$13:$A$269,$B$12,AT13:AT269) -> 0 | AU12: =IF(AT12="","",AT12/$E12) -> 0 | AV12: =AU12+AS12 -> 0.99046778 | AW12: =SUMIF($A$13:$A$269,$B$12,AW13:AW269) -> 0 | AX12: =IF(AW12="","",AW12/$E12) -> 0 | AY12: =AX12+AV12 -> 0.99046778 | AZ12: =SUMIF($A$13:$A$269,$B$12,AZ13:AZ269) -> 0 | BA12: =IF(AZ12="","",AZ12/$E12) -> 0 | BB12: =BA12+AY12 -> 0.99046778 | BC12: =SUMIF($A$13:$A$269,$B$12,BC13:BC269) -> 0 | BD12: =IF(BC12="","",BC12/$E12) -> 0 | BE12: =BD12+BB12 -> 0.99046778 | BF12: =SUMIF($A$13:$A$269,$B$12,BF13:BF269) -> 0 | BG12: =IF(BF12="","",BF12/$E12) -> 0 | BH12: =BG12+BE12 -> 0.99046778 | BI12: =SUMIF($A$13:$A$269,$B$12,BI13:BI269) -> 0 | BJ12: =IF(BI12="","",BI12/$E12) -> 0 | BK12: =BJ12+BH12 -> 0.99046778 | BL12: =SUMIF($A$13:$A$269,$B$12,BL13:BL269) -> 0 | BM12: =IF(BL12="","",BL12/$E12) -> 0 | BN12: =BM12+BK12 -> 0.99046778 | BO12: =SUMIF($A$13:$A$269,$B$12,BO13:BO269) -> 0 | BP12: =IF(BO12="","",BO12/$E12) -> 0 | BQ12: =BP12+BN12 -> 0.99046778 | BR12: =SUMIF($A$13:$A$269,$B$12,BR13:BR269) -> 0 | BS12: =IF(BR12="","",BR12/$E12) -> 0 | BT12: =BS12+BQ12 -> 0.99046778 | BU12: =SUMIF($A$13:$A$269,$B$12,BU13:BU269) -> 0 | BV12: =IF(BU12="","",BU12/$E12) -> 0 | BW12: =BV12+BT12 -> 0.99046778 | BX12: =SUMIF($A$13:$A$269,$B$12,BX13:BX269) -> 0 | BY12: =IF(BX12="","",BX12/$E12) -> 0 | BZ12: =BY12+BW12 -> 0.99046778 | CA12: =SUMIF($A$13:$A$269,$B$12,CA13:CA269) -> 0 | CB12: =IF(CA12="","",CA12/$E12) -> 0 | CC12: =CB12+BZ12 -> 0.99046778 | CD12: =SUMIF($A$13:$A$269,$B$12,CD13:CD269) -> 0 | CE12: =IF(CD12="","",CD12/$E12) -> 0 | CF12: =CE12+CC12 -> 0.99046778 | CG12: =SUMIF($A$13:$A$269,$B$12,CG13:CG269) -> 0 | CH12: =IF(CG12="","",CG12/$E12) -> 0 | CI12: =CH12+CF12 -> 0.99046778 | CJ12: =SUMIF($A$13:$A$269,$B$12,CJ13:CJ269) -> 0 | CK12: =IF(CJ12="","",CJ12/$E12) -> 0 | CL12: =CK12+CI12 -> 0.99046778 | CM12: =SUMIF($A$13:$A$269,$B$12,CM13:CM269) -> 0 | CN12: =IF(CM12="","",CM12/$E12) -> 0 | CO12: =CN12+CL12 -> 0.99046778 | CP12: =SUMIF($A$13:$A$269,$B$12,CP13:CP269) -> 0 | CQ12: =IF(CP12="","",CP12/$E12) -> 0 | CR12: =CQ12+CO12 -> 0.99046778 | CS12: =SUMIF($A$13:$A$269,$B$12,CS13:CS269) -> 0 | CT12: =IF(CS12="","",CS12/$E12) -> 0 | CU12: =CT12+CR12 -> 0.99046778 | CV12: =SUMIF($A$13:$A$269,$B$12,CV13:CV269) -> 0 | CW12: =IF(CV12="","",CV12/$E12) -> 0 | CX12: =CW12+CU12 -> 0.99046778 | CY12: =SUMIF($A$13:$A$269,$B$12,CY13:CY269) -> 0 | CZ12: =IF(CY12="","",CY12/$E12) -> 0 | DA12: =CZ12+CX12 -> 0.99046778 | DB12: =SUMIF($A$13:$A$269,$B$12,DB13:DB269) -> 0 | DC12: =IF(DB12="","",DB12/$E12) -> 0 | DD12: =DC12+DA12 -> 0.99046778 | DE12: =SUMIF($A$13:$A$269,$B$12,DE13:DE269) -> 0 | DF12: =IF(DE12="","",DE12/$E12) -> 0 | DG12: =DF12+DD12 -> 0.99046778 | DH12: =SUMIF($A$13:$A$269,$B$12,DH13:DH269) -> 0 | DI12: =IF(DH12="","",DH12/$E12) -> 0 | DJ12: =DI12+DG12 -> 0.99046778 | DK12: =G12+J12+M12+P12+S12+V12+Y12+AB12+AE12+AH12+AK12+AN12+AQ12+AT12+AW12+AZ12+BC12+BF12+BI12+BL12+BO12+BR12+BU12+BX12+CA12+CD12+CG12+CJ12+CM12+CP12+CS12+CV12+CY12+DB12+DE12+DH12 -> 678310.22 | DL12: =E12-DK12 -> 6528.03 | DM12: =DK12/E12 -> 0.99046778
A13: =LEFT(B13,1) -> 1 | B13: 1.1 | C13: LIGAÇÕES PROVISORIAS / CANTEIRO DE OBRAS | E13: =VLOOKUP(B13,'[49]PLANILHA ORCAMENTARIA'!A:G,7,0) -> 254900.14 | G13: =IF(H13="","",H13*$E13) | I13: =H13 -> 0 | J13: =IF(K13="","",K13*$E13) | L13: =K13+I13 -> 0 | M13: =IF(N13="","",N13*$E13) -> 254900.14 | N13: 1 | O13: =N13+L13 -> 1 | P13: =IF(Q13="","",Q13*$E13) | R13: =Q13+O13 -> 1 | S13: =IF(T13="","",T13*$E13) | U13: =T13+R13 -> 1 | V13: =IF(W13="","",W13*$E13) | X13: =W13+U13 -> 1 | Y13: =IF(Z13="","",Z13*$E13) | AA13: =Z13+X13 -> 1 | AB13: =IF(AC13="","",AC13*$E13) | AD13: =AC13+AA13 -> 1 | AE13: =IF(AF13="","",AF13*$E13) | AG13: =AF13+AD13 -> 1 | AH13: =IF(AI13="","",AI13*$E13) | AJ13: =AI13+AG13 -> 1 | AK13: =IF(AL13="","",AL13*$E13) | AM13: =AL13+AJ13 -> 1 | AN13: =IF(AO13="","",AO13*$E13) | AP13: =AO13+AM13 -> 1 | AQ13: =IF(AR13="","",AR13*$E13) | AS13: =AR13+AP13 -> 1 | AT13: =IF(AU13="","",AU13*$E13) | AV13: =AU13+AS13 -> 1 | AW13: =IF(AX13="","",AX13*$E13) | AY13: =AX13+AV13 -> 1 | AZ13: =IF(BA13="","",BA13*$E13) | BB13: =BA13+AY13 -> 1 | BC13: =IF(BD13="","",BD13*$E13) | BE13: =BD13+BB13 -> 1 | BF13: =IF(BG13="","",BG13*$E13) | BH13: =BG13+BE13 -> 1 | BI13: =IF(BJ13="","",BJ13*$E13) | BK13: =BJ13+BH13 -> 1 | BL13: =IF(BM13="","",BM13*$E13) | BN13: =BM13+BK13 -> 1 | BO13: =IF(BP13="","",BP13*$E13) | BQ13: =BP13+BN13 -> 1 | BR13: =IF(BS13="","",BS13*$E13) | BT13: =BS13+BQ13 -> 1 | BU13: =IF(BV13="","",BV13*$E13) | BW13: =BV13+BT13 -> 1 | BX13: =IF(BY13="","",BY13*$E13) | BZ13: =BY13+BW13 -> 1 | CA13: =IF(CB13="","",CB13*$E13) | CC13: =CB13+BZ13 -> 1 | CD13: =IF(CE13="","",CE13*$E13) | CF13: =CE13+CC13 -> 1 | CG13: =IF(CH13="","",CH13*$E13) | CI13: =CH13+CF13 -> 1 | CJ13: =IF(CK13="","",CK13*$E13) | CL13: =CK13+CI13 -> 1 | CM13: =IF(CN13="","",CN13*$E13) | CO13: =CN13+CL13 -> 1 | CP13: =IF(CQ13="","",CQ13*$E13) | CR13: =CQ13+CO13 -> 1 | CS13: =IF(CT13="","",CT13*$E13) | CU13: =CT13+CR13 -> 1 | CV13: =IF(CW13="","",CW13*$E13) | CX13: =CW13+CU13 -> 1 | CY13: =IF(CZ13="","",CZ13*$E13) | DA13: =CZ13+CX13 -> 1 | DB13: =IF(DC13="","",DC13*$E13) | DD13: =DC13+DA13 -> 1 | DE13: =IF(DF13="","",DF13*$E13) | DG13: =DF13+DD13 -> 1 | DH13: =IF(DI13="","",DI13*$E13) | DJ13: =DI13+DG13 -> 1
A14: =LEFT(B14,1) -> 1 | B14: 1.2 | C14: TAPUMES | E14: =VLOOKUP(B14,'[49]PLANILHA ORCAMENTARIA'!A:G,7,0) -> 83294.2 | G14: =IF(H14="","",H14*$E14) | I14: =H14 -> 0 | J14: =IF(K14="","",K14*$E14) | L14: =K14+I14 -> 0 | M14: =IF(N14="","",N14*$E14) -> 83294.2 | N14: 1 | O14: =N14+L14 -> 1 | P14: =IF(Q14="","",Q14*$E14) | R14: =Q14+O14 -> 1 | S14: =IF(T14="","",T14*$E14) | U14: =T14+R14 -> 1 | V14: =IF(W14="","",W14*$E14) | X14: =W14+U14 -> 1 | Y14: =IF(Z14="","",Z14*$E14) | AA14: =Z14+X14 -> 1 | AB14: =IF(AC14="","",AC14*$E14) | AD14: =AC14+AA14 -> 1 | AE14: =IF(AF14="","",AF14*$E14) | AG14: =AF14+AD14 -> 1 | AH14: =IF(AI14="","",AI14*$E14) | AJ14: =AI14+AG14 -> 1 | AK14: =IF(AL14="","",AL14*$E14) | AM14: =AL14+AJ14 -> 1 | AN14: =IF(AO14="","",AO14*$E14) | AP14: =AO14+AM14 -> 1 | AQ14: =IF(AR14="","",AR14*$E14) | AS14: =AR14+AP14 -> 1 | AT14: =IF(AU14="","",AU14*$E14) | AV14: =AU14+AS14 -> 1 | AW14: =IF(AX14="","",AX14*$E14) | AY14: =AX14+AV14 -> 1 | AZ14: =IF(BA14="","",BA14*$E14) | BB14: =BA14+AY14 -> 1 | BC14: =IF(BD14="","",BD14*$E14) | BE14: =BD14+BB14 -> 1 | BF14: =IF(BG14="","",BG14*$E14) | BH14: =BG14+BE14 -> 1 | BI14: =IF(BJ14="","",BJ14*$E14) | BK14: =BJ14+BH14 -> 1 | BL14: =IF(BM14="","",BM14*$E14) | BN14: =BM14+BK14 -> 1 | BO14: =IF(BP14="","",BP14*$E14) | BQ14: =BP14+BN14 -> 1 | BR14: =IF(BS14="","",BS14*$E14) | BT14: =BS14+BQ14 -> 1 | BU14: =IF(BV14="","",BV14*$E14) | BW14: =BV14+BT14 -> 1 | BX14: =IF(BY14="","",BY14*$E14) | BZ14: =BY14+BW14 -> 1 | CA14: =IF(CB14="","",CB14*$E14) | CC14: =CB14+BZ14 -> 1 | CD14: =IF(CE14="","",CE14*$E14) | CF14: =CE14+CC14 -> 1 | CG14: =IF(CH14="","",CH14*$E14) | CI14: =CH14+CF14 -> 1 | CJ14: =IF(CK14="","",CK14*$E14) | CL14: =CK14+CI14 -> 1 | CM14: =IF(CN14="","",CN14*$E14) | CO14: =CN14+CL14 -> 1 | CP14: =IF(CQ14="","",CQ14*$E14) | CR14: =CQ14+CO14 -> 1 | CS14: =IF(CT14="","",CT14*$E14) | CU14: =CT14+CR14 -> 1 | CV14: =IF(CW14="","",CW14*$E14) | CX14: =CW14+CU14 -> 1 | CY14: =IF(CZ14="","",CZ14*$E14) | DA14: =CZ14+CX14 -> 1 | DB14: =IF(DC14="","",DC14*$E14) | DD14: =DC14+DA14 -> 1 | DE14: =IF(DF14="","",DF14*$E14) | DG14: =DF14+DD14 -> 1 | DH14: =IF(DI14="","",DI14*$E14) | DJ14: =DI14+DG14 -> 1
A15: =LEFT(B15,1) -> 1 | B15: 1.3 | C15: LOCAÇÃO DA OBRA | E15: =VLOOKUP(B15,'[49]PLANILHA ORCAMENTARIA'!A:G,7,0) -> 113076.45 | G15: =IF(H15="","",H15*$E15) | I15: =H15 -> 0 | J15: =IF(K15="","",K15*$E15) | L15: =K15+I15 -> 0 | M15: =IF(N15="","",N15*$E15) | O15: =N15+L15 -> 0 | P15: =IF(Q15="","",Q15*$E15) -> 113076.45 | Q15: 1 | R15: =Q15+O15 -> 1 | S15: =IF(T15="","",T15*$E15) | U15: =T15+R15 -> 1 | V15: =IF(W15="","",W15*$E15) | X15: =W15+U15 -> 1 | Y15: =IF(Z15="","",Z15*$E15) | AA15: =Z15+X15 -> 1 | AB15: =IF(AC15="","",AC15*$E15) | AD15: =AC15+AA15 -> 1 | AE15: =IF(AF15="","",AF15*$E15) | AG15: =AF15+AD15 -> 1 | AH15: =IF(AI15="","",AI15*$E15) | AJ15: =AI15+AG15 -> 1 | AK15: =IF(AL15="","",AL15*$E15) | AM15: =AL15+AJ15 -> 1 | AN15: =IF(AO15="","",AO15*$E15) | AP15: =AO15+AM15 -> 1 | AQ15: =IF(AR15="","",AR15*$E15) | AS15: =AR15+AP15 -> 1 | AT15: =IF(AU15="","",AU15*$E15) | AV15: =AU15+AS15 -> 1 | AW15: =IF(AX15="","",AX15*$E15) | AY15: =AX15+AV15 -> 1 | AZ15: =IF(BA15="","",BA15*$E15) | BB15: =BA15+AY15 -> 1 | BC15: =IF(BD15="","",BD15*$E15) | BE15: =BD15+BB15 -> 1 | BF15: =IF(BG15="","",BG15*$E15) | BH15: =BG15+BE15 -> 1 | BI15: =IF(BJ15="","",BJ15*$E15) | BK15: =BJ15+BH15 -> 1 | BL15: =IF(BM15="","",BM15*$E15) | BN15: =BM15+BK15 -> 1 | BO15: =IF(BP15="","",BP15*$E15) | BQ15: =BP15+BN15 -> 1 | BR15: =IF(BS15="","",BS15*$E15) | BT15: =BS15+BQ15 -> 1 | BU15: =IF(BV15="","",BV15*$E15) | BW15: =BV15+BT15 -> 1 | BX15: =IF(BY15="","",BY15*$E15) | BZ15: =BY15+BW15 -> 1 | CA15: =IF(CB15="","",CB15*$E15) | CC15: =CB15+BZ15 -> 1 | CD15: =IF(CE15="","",CE15*$E15) | CF15: =CE15+CC15 -> 1 | CG15: =IF(CH15="","",CH15*$E15) | CI15: =CH15+CF15 -> 1 | CJ15: =IF(CK15="","",CK15*$E15) | CL15: =CK15+CI15 -> 1 | CM15: =IF(CN15="","",CN15*$E15) | CO15: =CN15+CL15 -> 1 | CP15: =IF(CQ15="","",CQ15*$E15) | CR15: =CQ15+CO15 -> 1 | CS15: =IF(CT15="","",CT15*$E15) | CU15: =CT15+CR15 -> 1 | CV15: =IF(CW15="","",CW15*$E15) | CX15: =CW15+CU15 -> 1 | CY15: =IF(CZ15="","",CZ15*$E15) | DA15: =CZ15+CX15 -> 1 | DB15: =IF(DC15="","",DC15*$E15) | DD15: =DC15+DA15 -> 1 | DE15: =IF(DF15="","",DF15*$E15) | DG15: =DF15+DD15 -> 1 | DH15: =IF(DI15="","",DI15*$E15) | DJ15: =DI15+DG15 -> 1
A16: =LEFT(B16,1) -> 1 | B16: 1.4 | C16: TERRAPLANAGEM | E16: =VLOOKUP(B16,'[49]PLANILHA ORCAMENTARIA'!A:G,7,0) -> 227039.43 | G16: =IF(H16="","",H16*$E16) | I16: =H16 -> 0 | J16: =IF(K16="","",K16*$E16) | L16: =K16+I16 -> 0 | M16: =IF(N16="","",N16*$E16) | O16: =N16+L16 -> 0 | P16: =IF(Q16="","",Q16*$E16) -> 227039.43 | Q16: 1 | R16: =Q16+O16 -> 1 | S16: =IF(T16="","",T16*$E16) | U16: =T16+R16 -> 1 | V16: =IF(W16="","",W16*$E16) | X16: =W16+U16 -> 1 | Y16: =IF(Z16="","",Z16*$E16) | AA16: =Z16+X16 -> 1 | AB16: =IF(AC16="","",AC16*$E16) | AD16: =AC16+AA16 -> 1 | AE16: =IF(AF16="","",AF16*$E16) | AG16: =AF16+AD16 -> 1 | AH16: =IF(AI16="","",AI16*$E16) | AJ16: =AI16+AG16 -> 1 | AK16: =IF(AL16="","",AL16*$E16) | AM16: =AL16+AJ16 -> 1 | AN16: =IF(AO16="","",AO16*$E16) | AP16: =AO16+AM16 -> 1 | AQ16: =IF(AR16="","",AR16*$E16) | AS16: =AR16+AP16 -> 1 | AT16: =IF(AU16="","",AU16*$E16) | AV16: =AU16+AS16 -> 1 | AW16: =IF(AX16="","",AX16*$E16) | AY16: =AX16+AV16 -> 1 | AZ16: =IF(BA16="","",BA16*$E16) | BB16: =BA16+AY16 -> 1 | BC16: =IF(BD16="","",BD16*$E16) | BE16: =BD16+BB16 -> 1 | BF16: =IF(BG16="","",BG16*$E16) | BH16: =BG16+BE16 -> 1 | BI16: =IF(BJ16="","",BJ16*$E16) | BK16: =BJ16+BH16 -> 1 | BL16: =IF(BM16="","",BM16*$E16) | BN16: =BM16+BK16 -> 1 | BO16: =IF(BP16="","",BP16*$E16) | BQ16: =BP16+BN16 -> 1 | BR16: =IF(BS16="","",BS16*$E16) | BT16: =BS16+BQ16 -> 1 | BU16: =IF(BV16="","",BV16*$E16) | BW16: =BV16+BT16 -> 1 | BX16: =IF(BY16="","",BY16*$E16) | BZ16: =BY16+BW16 -> 1 | CA16: =IF(CB16="","",CB16*$E16) | CC16: =CB16+BZ16 -> 1 | CD16: =IF(CE16="","",CE16*$E16) | CF16: =CE16+CC16 -> 1 | CG16: =IF(CH16="","",CH16*$E16) | CI16: =CH16+CF16 -> 1 | CJ16: =IF(CK16="","",CK16*$E16) | CL16: =CK16+CI16 -> 1 | CM16: =IF(CN16="","",CN16*$E16) | CO16: =CN16+CL16 -> 1 | CP16: =IF(CQ16="","",CQ16*$E16) | CR16: =CQ16+CO16 -> 1 | CS16: =IF(CT16="","",CT16*$E16) | CU16: =CT16+CR16 -> 1 | CV16: =IF(CW16="","",CW16*$E16) | CX16: =CW16+CU16 -> 1 | CY16: =IF(CZ16="","",CZ16*$E16) | DA16: =CZ16+CX16 -> 1 | DB16: =IF(DC16="","",DC16*$E16) | DD16: =DC16+DA16 -> 1 | DE16: =IF(DF16="","",DF16*$E16) | DG16: =DF16+DD16 -> 1 | DH16: =IF(DI16="","",DI16*$E16) | DJ16: =DI16+DG16 -> 1
A17: =LEFT(B17,1) -> 1 | B17: 1.5 | C17: POÇO PROFUNDO | E17: =VLOOKUP(B17,'[49]PLANILHA ORCAMENTARIA'!A:G,7,0) -> 6528.03 | G17: =IF(H17="","",H17*$E17) | I17: =H17 -> 0 | J17: =IF(K17="","",K17*$E17) | L17: =K17+I17 -> 0 | M17: =IF(N17="","",N17*$E17) | O17: =N17+L17 -> 0 | P17: =IF(Q17="","",Q17*$E17) | R17: =Q17+O17 -> 0 | S17: =IF(T17="","",T17*$E17) | U17: =T17+R17 -> 0 | V17: =IF(W17="","",W17*$E17) | X17: =W17+U17 -> 0 | Y17: =IF(Z17="","",Z17*$E17) | AA17: =Z17+X17 -> 0 | AB17: =IF(AC17="","",AC17*$E17) | AD17: =AC17+AA17 -> 0 | AE17: =IF(AF17="","",AF17*$E17) | AG17: =AF17+AD17 -> 0 | AH17: =IF(AI17="","",AI17*$E17) | AJ17: =AI17+AG17 -> 0 | AK17: =IF(AL17="","",AL17*$E17) | AM17: =AL17+AJ17 -> 0 | AN17: =IF(AO17="","",AO17*$E17) | AP17: =AO17+AM17 -> 0 | AQ17: =IF(AR17="","",AR17*$E17) | AS17: =AR17+AP17 -> 0 | AT17: =IF(AU17="","",AU17*$E17) | AV17: =AU17+AS17 -> 0 | AW17: =IF(AX17="","",AX17*$E17) | AY17: =AX17+AV17 -> 0 | AZ17: =IF(BA17="","",BA17*$E17) | BB17: =BA17+AY17 -> 0 | BC17: =IF(BD17="","",BD17*$E17) | BE17: =BD17+BB17 -> 0 | BF17: =IF(BG17="","",BG17*$E17) | BH17: =BG17+BE17 -> 0 | BI17: =IF(BJ17="","",BJ17*$E17) | BK17: =BJ17+BH17 -> 0 | BL17: =IF(BM17="","",BM17*$E17) | BN17: =BM17+BK17 -> 0 | BO17: =IF(BP17="","",BP17*$E17) | BQ17: =BP17+BN17 -> 0 | BR17: =IF(BS17="","",BS17*$E17) | BT17: =BS17+BQ17 -> 0 | BU17: =IF(BV17="","",BV17*$E17) | BW17: =BV17+BT17 -> 0 | BX17: =IF(BY17="","",BY17*$E17) | BZ17: =BY17+BW17 -> 0 | CA17: =IF(CB17="","",CB17*$E17) | CC17: =CB17+BZ17 -> 0 | CD17: =IF(CE17="","",CE17*$E17) | CF17: =CE17+CC17 -> 0 | CG17: =IF(CH17="","",CH17*$E17) | CI17: =CH17+CF17 -> 0 | CJ17: =IF(CK17="","",CK17*$E17) | CL17: =CK17+CI17 -> 0 | CM17: =IF(CN17="","",CN17*$E17) | CO17: =CN17+CL17 -> 0 | CP17: =IF(CQ17="","",CQ17*$E17) | CR17: =CQ17+CO17 -> 0 | CS17: =IF(CT17="","",CT17*$E17) | CU17: =CT17+CR17 -> 0 | CV17: =IF(CW17="","",CW17*$E17) | CX17: =CW17+CU17 -> 0 | CY17: =IF(CZ17="","",CZ17*$E17) | DA17: =CZ17+CX17 -> 0 | DB17: =IF(DC17="","",DC17*$E17) | DD17: =DC17+DA17 -> 0 | DE17: =IF(DF17="","",DF17*$E17) | DG17: =DF17+DD17 -> 0 | DH17: =IF(DI17="","",DI17*$E17) | DJ17: =DI17+DG17 -> 0
A18: =LEFT(B18,1) -> 2 | B18: 2 | C18: ADMINISTRAÇÃO DA OBRA | E18: =VLOOKUP(B18,'[49]PLANILHA ORCAMENTARIA'!A:G,7,0) -> 2333205.8 | G18: =ROUND((G12+G19+G72+G221+G226+G247+G259+G265+G268)*$F$6,2) -> 0 | H18: =IF(G18="","",G18/$E18) -> 0 | I18: =H18 -> 0 | J18: =ROUND((J12+J19+J72+J221+J226+J247+J259+J265+J268)*$F$6,2) -> 0 | K18: =IF(J18="","",J18/$E18) -> 0 | L18: =K18+I18 -> 0 | M18: =ROUND((M12+M19+M72+M221+M226+M247+M259+M265+M268)*$F$6,2) -> 30078.93 | N18: =IF(M18="","",M18/$E18) -> 0.012891674 | O18: =N18+L18 -> 0.012891674 | P18: =ROUND((P12+P19+P72+P221+P226+P247+P259+P265+P268)*$F$6,2) -> 79105.47 | Q18: =IF(P18="","",P18/$E18) -> 0.033904197 | R18: =Q18+O18 -> 0.046795871 | S18: =ROUND((S12+S19+S72+S221+S226+S247+S259+S265+S268)*$F$6,2) -> 82391.2 | T18: =IF(S18="","",S18/$E18) -> 0.035312444 | U18: =T18+R18 -> 0.082108315 | V18: =ROUND((V12+V19+V72+V221+V226+V247+V259+V265+V268)*$F$6,2) -> 0 | W18: =IF(V18="","",V18/$E18) -> 0 | X18: =W18+U18 -> 0.082108315 | Y18: =ROUND((Y12+Y19+Y72+Y221+Y226+Y247+Y259+Y265+Y268)*$F$6,2) -> 0 | Z18: =IF(Y18="","",Y18/$E18) -> 0 | AA18: =Z18+X18 -> 0.082108315 | AB18: =ROUND((AB12+AB19+AB72+AB221+AB226+AB247+AB259+AB265+AB268)*$F$6,2) -> 0 | AC18: =IF(AB18="","",AB18/$E18) -> 0 | AD18: =AC18+AA18 -> 0.082108315 | AE18: =ROUND((AE12+AE19+AE72+AE221+AE226+AE247+AE259+AE265+AE268)*$F$6,2) -> 0 | AF18: =IF(AE18="","",AE18/$E18) -> 0 | AG18: =AF18+AD18 -> 0.082108315 | AH18: =ROUND((AH12+AH19+AH72+AH221+AH226+AH247+AH259+AH265+AH268)*$F$6,2) -> 0 | AI18: =IF(AH18="","",AH18/$E18) -> 0 | AJ18: =AI18+AG18 -> 0.082108315 | AK18: =ROUND((AK12+AK19+AK72+AK221+AK226+AK247+AK259+AK265+AK268)*$F$6,2) -> 0 | AL18: =IF(AK18="","",AK18/$E18) -> 0 | AM18: =AL18+AJ18 -> 0.082108315 | AN18: =ROUND((AN12+AN19+AN72+AN221+AN226+AN247+AN259+AN265+AN268)*$F$6,2) -> 0 | AO18: =IF(AN18="","",AN18/$E18) -> 0 | AP18: =AO18+AM18 -> 0.082108315 | AQ18: =ROUND((AQ12+AQ19+AQ72+AQ221+AQ226+AQ247+AQ259+AQ265+AQ268)*$F$6,2) -> 0 | AR18: =IF(AQ18="","",AQ18/$E18) -> 0 | AS18: =AR18+AP18 -> 0.082108315 | AT18: =ROUND((AT12+AT19+AT72+AT221+AT226+AT247+AT259+AT265+AT268)*$F$6,2) -> 0 | AU18: =IF(AT18="","",AT18/$E18) -> 0 | AV18: =AU18+AS18 -> 0.082108315 | AW18: =ROUND((AW12+AW19+AW72+AW221+AW226+AW247+AW259+AW265+AW268)*$F$6,2) -> 0 | AX18: =IF(AW18="","",AW18/$E18) -> 0 | AY18: =AX18+AV18 -> 0.082108315 | AZ18: =ROUND((AZ12+AZ19+AZ72+AZ221+AZ226+AZ247+AZ259+AZ265+AZ268)*$F$6,2) -> 0 | BA18: =IF(AZ18="","",AZ18/$E18) -> 0 | BB18: =BA18+AY18 -> 0.082108315 | BC18: =ROUND((BC12+BC19+BC72+BC221+BC226+BC247+BC259+BC265+BC268)*$F$6,2) -> 0 | BD18: =IF(BC18="","",BC18/$E18) -> 0 | BE18: =BD18+BB18 -> 0.082108315 | BF18: =ROUND((BF12+BF19+BF72+BF221+BF226+BF247+BF259+BF265+BF268)*$F$6,2) -> 0 | BG18: =IF(BF18="","",BF18/$E18) -> 0 | BH18: =BG18+BE18 -> 0.082108315 | BI18: =ROUND((BI12+BI19+BI72+BI221+BI226+BI247+BI259+BI265+BI268)*$F$6,2) -> 0 | BJ18: =IF(BI18="","",BI18/$E18) -> 0 | BK18: =BJ18+BH18 -> 0.082108315 | BL18: =ROUND((BL12+BL19+BL72+BL221+BL226+BL247+BL259+BL265+BL268)*$F$6,2) -> 0 | BM18: =IF(BL18="","",BL18/$E18) -> 0 | BN18: =BM18+BK18 -> 0.082108315 | BO18: =ROUND((BO12+BO19+BO72+BO221+BO226+BO247+BO259+BO265+BO268)*$F$6,2) -> 0 | BP18: =IF(BO18="","",BO18/$E18) -> 0 | BQ18: =BP18+BN18 -> 0.082108315 | BR18: =ROUND((BR12+BR19+BR72+BR221+BR226+BR247+BR259+BR265+BR268)*$F$6,2) -> 0 | BS18: =IF(BR18="","",BR18/$E18) -> 0 | BT18: =BS18+BQ18 -> 0.082108315 | BU18: =ROUND((BU12+BU19+BU72+BU221+BU226+BU247+BU259+BU265+BU268)*$F$6,2) -> 0 | BV18: =IF(BU18="","",BU18/$E18) -> 0 | BW18: =BV18+BT18 -> 0.082108315 | BX18: =ROUND((BX12+BX19+BX72+BX221+BX226+BX247+BX259+BX265+BX268)*$F$6,2) -> 0 | BY18: =IF(BX18="","",BX18/$E18) -> 0 | BZ18: =BY18+BW18 -> 0.082108315 | CA18: =ROUND((CA12+CA19+CA72+CA221+CA226+CA247+CA259+CA265+CA268)*$F$6,2) -> 0 | CB18: =IF(CA18="","",CA18/$E18) -> 0 | CC18: =CB18+BZ18 -> 0.082108315 | CD18: =ROUND((CD12+CD19+CD72+CD221+CD226+CD247+CD259+CD265+CD268)*$F$6,2) -> 0 | CE18: =IF(CD18="","",CD18/$E18) -> 0 | CF18: =CE18+CC18 -> 0.082108315 | CG18: =ROUND((CG12+CG19+CG72+CG221+CG226+CG247+CG259+CG265+CG268)*$F$6,2) -> 0 | CH18: =IF(CG18="","",CG18/$E18) -> 0 | CI18: =CH18+CF18 -> 0.082108315 | CJ18: =ROUND((CJ12+CJ19+CJ72+CJ221+CJ226+CJ247+CJ259+CJ265+CJ268)*$F$6,2) -> 0 | CK18: =IF(CJ18="","",CJ18/$E18) -> 0 | CL18: =CK18+CI18 -> 0.082108315 | CM18: =ROUND((CM12+CM19+CM72+CM221+CM226+CM247+CM259+CM265+CM268)*$F$6,2) -> 0 | CN18: =IF(CM18="","",CM18/$E18) -> 0 | CO18: =CN18+CL18 -> 0.082108315 | CP18: =ROUND((CP12+CP19+CP72+CP221+CP226+CP247+CP259+CP265+CP268)*$F$6,2) -> 0 | CQ18: =IF(CP18="","",CP18/$E18) -> 0 | CR18: =CQ18+CO18 -> 0.082108315 | CS18: =ROUND((CS12+CS19+CS72+CS221+CS226+CS247+CS259+CS265+CS268)*$F$6,2) -> 0 | CT18: =IF(CS18="","",CS18/$E18) -> 0 | CU18: =CT18+CR18 -> 0.082108315 | CV18: =ROUND((CV12+CV19+CV72+CV221+CV226+CV247+CV259+CV265+CV268)*$F$6,2) -> 0 | CW18: =IF(CV18="","",CV18/$E18) -> 0 | CX18: =CW18+CU18 -> 0.082108315 | CY18: =ROUND((CY12+CY19+CY72+CY221+CY226+CY247+CY259+CY265+CY268)*$F$6,2) -> 0 | CZ18: =IF(CY18="","",CY18/$E18) -> 0 | DA18: =CZ18+CX18 -> 0.082108315 | DB18: =ROUND((DB12+DB19+DB72+DB221+DB226+DB247+DB259+DB265+DB268)*$F$6,2) -> 0 | DC18: =IF(DB18="","",DB18/$E18) -> 0 | DD18: =DC18+DA18 -> 0.082108315 | DE18: =ROUND((DE12+DE19+DE72+DE221+DE226+DE247+DE259+DE265+DE268)*$F$6,2) -> 0 | DF18: =IF(DE18="","",DE18/$E18) -> 0 | DG18: =DF18+DD18 -> 0.082108315 | DH18: =ROUND((DH12+DH19+DH72+DH221+DH226+DH247+DH259+DH265+DH268)*$F$6,2) -> 0 | DI18: =IF(DH18="","",DH18/$E18) -> 0 | DJ18: =DI18+DG18 -> 0.082108315 | DK18: =G18+J18+M18+P18+S18+V18+Y18+AB18+AE18+AH18+AK18+AN18+AQ18+AT18+AW18+AZ18+BC18+BF18+BI18+BL18+BO18+BR18+BU18+BX18+CA18+CD18+CG18+CJ18+CM18+CP18+CS18+CV18+CY18+DB18+DE18+DH18 -> 191575.6 | DL18: =E18-DK18 -> 2141630.2 | DM18: =DK18/E18 -> 0.082108315
A19: 3 | B19: 3 | C19: FUNDAÇÕES E ESTRUTURAS | E19: =VLOOKUP(B19,'[49]PLANILHA ORCAMENTARIA'!A:G,7,0) -> 6067667.4 | G19: =SUM(G20:G71) -> 0 | H19: =IF(G19="","",G19/$E19) -> 0 | I19: =H19 -> 0 | J19: =SUM(J20:J71) -> 0 | K19: =IF(J19="","",J19/$E19) -> 0 | L19: =K19+I19 -> 0 | M19: =SUM(M20:M71) -> 0 | N19: =IF(M19="","",M19/$E19) -> 0 | O19: =N19+L19 -> 0 | P19: =SUM(P20:P71) -> 549311.32 | Q19: =IF(P19="","",P19/$E19) -> 0.090530888 | R19: =Q19+O19 -> 0.090530888 | S19: =SUM(S20:S71) -> 926370.58 | T19: =IF(S19="","",S19/$E19) -> 0.15267326 | U19: =T19+R19 -> 0.24320415 | V19: =SUM(V20:V71) -> 0 | W19: =IF(V19="","",V19/$E19) -> 0 | X19: =W19+U19 -> 0.24320415 | Y19: =SUM(Y20:Y71) -> 0 | Z19: =IF(Y19="","",Y19/$E19) -> 0 | AA19: =Z19+X19 -> 0.24320415 | AB19: =SUM(AB20:AB71) -> 0 | AC19: =IF(AB19="","",AB19/$E19) -> 0 | AD19: =AC19+AA19 -> 0.24320415 | AE19: =SUM(AE20:AE71) -> 0 | AF19: =IF(AE19="","",AE19/$E19) -> 0 | AG19: =AF19+AD19 -> 0.24320415 | AH19: =SUM(AH20:AH71) -> 0 | AI19: =IF(AH19="","",AH19/$E19) -> 0 | AJ19: =AI19+AG19 -> 0.24320415 | AK19: =SUM(AK20:AK71) -> 0 | AL19: =IF(AK19="","",AK19/$E19) -> 0 | AM19: =AL19+AJ19 -> 0.24320415 | AN19: =SUM(AN20:AN71) -> 0 | AO19: =IF(AN19="","",AN19/$E19) -> 0 | AP19: =AO19+AM19 -> 0.24320415 | AQ19: =SUM(AQ20:AQ71) -> 0 | AR19: =IF(AQ19="","",AQ19/$E19) -> 0 | AS19: =AR19+AP19 -> 0.24320415 | AT19: =SUM(AT20:AT71) -> 0 | AU19: =IF(AT19="","",AT19/$E19) -> 0 | AV19: =AU19+AS19 -> 0.24320415 | AW19: =SUM(AW20:AW71) -> 0 | AX19: =IF(AW19="","",AW19/$E19) -> 0 | AY19: =AX19+AV19 -> 0.24320415 | AZ19: =SUM(AZ20:AZ71) -> 0 | BA19: =IF(AZ19="","",AZ19/$E19) -> 0 | BB19: =BA19+AY19 -> 0.24320415 | BC19: =SUM(BC20:BC71) -> 0 | BD19: =IF(BC19="","",BC19/$E19) -> 0 | BE19: =BD19+BB19 -> 0.24320415 | BF19: =SUM(BF20:BF71) -> 0 | BG19: =IF(BF19="","",BF19/$E19) -> 0 | BH19: =BG19+BE19 -> 0.24320415 | BI19: =SUM(BI20:BI71) -> 0 | BJ19: =IF(BI19="","",BI19/$E19) -> 0 | BK19: =BJ19+BH19 -> 0.24320415 | BL19: =SUM(BL20:BL71) -> 0 | BM19: =IF(BL19="","",BL19/$E19) -> 0 | BN19: =BM19+BK19 -> 0.24320415 | BO19: =SUM(BO20:BO71) -> 0 | BP19: =IF(BO19="","",BO19/$E19) -> 0 | BQ19: =BP19+BN19 -> 0.24320415 | BR19: =SUM(BR20:BR71) -> 0 | BS19: =IF(BR19="","",BR19/$E19) -> 0 | BT19: =BS19+BQ19 -> 0.24320415 | BU19: =SUM(BU20:BU71) -> 0 | BV19: =IF(BU19="","",BU19/$E19) -> 0 | BW19: =BV19+BT19 -> 0.24320415 | BX19: =SUM(BX20:BX71) -> 0 | BY19: =IF(BX19="","",BX19/$E19) -> 0 | BZ19: =BY19+BW19 -> 0.24320415 | CA19: =SUM(CA20:CA71) -> 0 | CB19: =IF(CA19="","",CA19/$E19) -> 0 | CC19: =CB19+BZ19 -> 0.24320415 | CD19: =SUM(CD20:CD71) -> 0 | CE19: =IF(CD19="","",CD19/$E19) -> 0 | CF19: =CE19+CC19 -> 0.24320415 | CG19: =SUM(CG20:CG71) -> 0 | CH19: =IF(CG19="","",CG19/$E19) -> 0 | CI19: =CH19+CF19 -> 0.24320415 | CJ19: =SUM(CJ20:CJ71) -> 0 | CK19: =IF(CJ19="","",CJ19/$E19) -> 0 | CL19: =CK19+CI19 -> 0.24320415 | CM19: =SUM(CM20:CM71) -> 0 | CN19: =IF(CM19="","",CM19/$E19) -> 0 | CO19: =CN19+CL19 -> 0.24320415 | CP19: =SUM(CP20:CP71) -> 0 | CQ19: =IF(CP19="","",CP19/$E19) -> 0 | CR19: =CQ19+CO19 -> 0.24320415 | CS19: =SUM(CS20:CS71) -> 0 | CT19: =IF(CS19="","",CS19/$E19) -> 0 | CU19: =CT19+CR19 -> 0.24320415 | CV19: =SUM(CV20:CV71) -> 0 | CW19: =IF(CV19="","",CV19/$E19) -> 0 | CX19: =CW19+CU19 -> 0.24320415 | CY19: =SUM(CY20:CY71) -> 0 | CZ19: =IF(CY19="","",CY19/$E19) -> 0 | DA19: =CZ19+CX19 -> 0.24320415 | DB19: =SUM(DB20:DB71) -> 0 | DC19: =IF(DB19="","",DB19/$E19) -> 0 | DD19: =DC19+DA19 -> 0.24320415 | DE19: =SUM(DE20:DE71) -> 0 | DF19: =IF(DE19="","",DE19/$E19) -> 0 | DG19: =DF19+DD19 -> 0.24320415 | DH19: =SUM(DH20:DH71) -> 0 | DI19: =IF(DH19="","",DH19/$E19) -> 0 | DJ19: =DI19+DG19 -> 0.24320415 | DK19: =G19+J19+M19+P19+S19+V19+Y19+AB19+AE19+AH19+AK19+AN19+AQ19+AT19+AW19+AZ19+BC19+BF19+BI19+BL19+BO19+BR19+BU19+BX19+CA19+CD19+CG19+CJ19+CM19+CP19+CS19+CV19+CY19+DB19+DE19+DH19 -> 1475681.9 | DL19: =E19-DK19 -> 4591985.5 | DM19: =DK19/E19 -> 0.24320415
A20: 3 | B20: 3.1 | C20: FUNDAÇÕES | E20: =VLOOKUP(B20,'[49]PLANILHA ORCAMENTARIA'!A:G,7,0) -> 1777201.7
A21: 3 | B21: 3.1.1 | C21: BLOCO PRINCIPAL | E21: =VLOOKUP(B21,'[49]PLANILHA ORCAMENTARIA'!A:G,7,0) -> 1605873.1
A22: 3 | B22: 3.1.1.1 | C22: CONTENÇÃO | E22: =VLOOKUP(B22,'[49]PLANILHA ORCAMENTARIA'!A:G,7,0) -> 526764.81
A23: 3 | B23: 3.1.1.1.1 | C23: ESTACA ESCAVADA | E23: =VLOOKUP(B23,'[49]PLANILHA ORCAMENTARIA'!A:G,7,0) -> 158144.41 | G23: =IF(H23="","",H23*$E23) | I23: =H23 -> 0 | J23: =IF(K23="","",K23*$E23) | L23: =K23+I23 -> 0 | M23: =IF(N23="","",N23*$E23) | O23: =N23+L23 -> 0 | P23: =IF(Q23="","",Q23*$E23) -> 158144.41 | Q23: 1 | R23: =Q23+O23 -> 1 | S23: =IF(T23="","",T23*$E23) | U23: =T23+R23 -> 1 | V23: =IF(W23="","",W23*$E23) | X23: =W23+U23 -> 1 | Y23: =IF(Z23="","",Z23*$E23) | AA23: =Z23+X23 -> 1 | AB23: =IF(AC23="","",AC23*$E23) | AD23: =AC23+AA23 -> 1 | AE23: =IF(AF23="","",AF23*$E23) | AG23: =AF23+AD23 -> 1 | AH23: =IF(AI23="","",AI23*$E23) | AJ23: =AI23+AG23 -> 1 | AK23: =IF(AL23="","",AL23*$E23) | AM23: =AL23+AJ23 -> 1 | AN23: =IF(AO23="","",AO23*$E23) | AP23: =AO23+AM23 -> 1 | AQ23: =IF(AR23="","",AR23*$E23) | AS23: =AR23+AP23 -> 1 | AT23: =IF(AU23="","",AU23*$E23) | AV23: =AU23+AS23 -> 1 | AW23: =IF(AX23="","",AX23*$E23) | AY23: =AX23+AV23 -> 1 | AZ23: =IF(BA23="","",BA23*$E23) | BB23: =BA23+AY23 -> 1 | BC23: =IF(BD23="","",BD23*$E23) | BE23: =BD23+BB23 -> 1 | BF23: =IF(BG23="","",BG23*$E23) | BH23: =BG23+BE23 -> 1 | BI23: =IF(BJ23="","",BJ23*$E23) | BK23: =BJ23+BH23 -> 1 | BL23: =IF(BM23="","",BM23*$E23) | BN23: =BM23+BK23 -> 1 | BO23: =IF(BP23="","",BP23*$E23) | BQ23: =BP23+BN23 -> 1 | BR23: =IF(BS23="","",BS23*$E23) | BT23: =BS23+BQ23 -> 1 | BU23: =IF(BV23="","",BV23*$E23) | BW23: =BV23+BT23 -> 1 | BX23: =IF(BY23="","",BY23*$E23) | BZ23: =BY23+BW23 -> 1 | CA23: =IF(CB23="","",CB23*$E23) | CC23: =CB23+BZ23 -> 1 | CD23: =IF(CE23="","",CE23*$E23) | CF23: =CE23+CC23 -> 1 | CG23: =IF(CH23="","",CH23*$E23) | CI23: =CH23+CF23 -> 1 | CJ23: =IF(CK23="","",CK23*$E23) | CL23: =CK23+CI23 -> 1 | CM23: =IF(CN23="","",CN23*$E23) | CO23: =CN23+CL23 -> 1 | CP23: =IF(CQ23="","",CQ23*$E23) | CR23: =CQ23+CO23 -> 1 | CS23: =IF(CT23="","",CT23*$E23) | CU23: =CT23+CR23 -> 1 | CV23: =IF(CW23="","",CW23*$E23) | CX23: =CW23+CU23 -> 1 | CY23: =IF(CZ23="","",CZ23*$E23) | DA23: =CZ23+CX23 -> 1 | DB23: =IF(DC23="","",DC23*$E23) | DD23: =DC23+DA23 -> 1 | DE23: =IF(DF23="","",DF23*$E23) | DG23: =DF23+DD23 -> 1 | DH23: =IF(DI23="","",DI23*$E23) | DJ23: =DI23+DG23 -> 1
A24: 3 | B24: 3.1.1.1.2 | C24: VIGA DE COROAMENTO | E24: =VLOOKUP(B24,'[49]PLANILHA ORCAMENTARIA'!A:G,7,0) -> 115741.02 | G24: =IF(H24="","",H24*$E24) | I24: =H24 -> 0 | J24: =IF(K24="","",K24*$E24) | L24: =K24+I24 -> 0 | M24: =IF(N24="","",N24*$E24) | O24: =N24+L24 -> 0 | P24: =IF(Q24="","",Q24*$E24) -> 115741.02 | Q24: 1 | R24: =Q24+O24 -> 1 | S24: =IF(T24="","",T24*$E24) | U24: =T24+R24 -> 1 | V24: =IF(W24="","",W24*$E24) | X24: =W24+U24 -> 1 | Y24: =IF(Z24="","",Z24*$E24) | AA24: =Z24+X24 -> 1 | AB24: =IF(AC24="","",AC24*$E24) | AD24: =AC24+AA24 -> 1 | AE24: =IF(AF24="","",AF24*$E24) | AG24: =AF24+AD24 -> 1 | AH24: =IF(AI24="","",AI24*$E24) | AJ24: =AI24+AG24 -> 1 | AK24: =IF(AL24="","",AL24*$E24) | AM24: =AL24+AJ24 -> 1 | AN24: =IF(AO24="","",AO24*$E24) | AP24: =AO24+AM24 -> 1 | AQ24: =IF(AR24="","",AR24*$E24) | AS24: =AR24+AP24 -> 1 | AT24: =IF(AU24="","",AU24*$E24) | AV24: =AU24+AS24 -> 1 | AW24: =IF(AX24="","",AX24*$E24) | AY24: =AX24+AV24 -> 1 | AZ24: =IF(BA24="","",BA24*$E24) | BB24: =BA24+AY24 -> 1 | BC24: =IF(BD24="","",BD24*$E24) | BE24: =BD24+BB24 -> 1 | BF24: =IF(BG24="","",BG24*$E24) | BH24: =BG24+BE24 -> 1 | BI24: =IF(BJ24="","",BJ24*$E24) | BK24: =BJ24+BH24 -> 1 | BL24: =IF(BM24="","",BM24*$E24) | BN24: =BM24+BK24 -> 1 | BO24: =IF(BP24="","",BP24*$E24) | BQ24: =BP24+BN24 -> 1 | BR24: =IF(BS24="","",BS24*$E24) | BT24: =BS24+BQ24 -> 1 | BU24: =IF(BV24="","",BV24*$E24) | BW24: =BV24+BT24 -> 1 | BX24: =IF(BY24="","",BY24*$E24) | BZ24: =BY24+BW24 -> 1 | CA24: =IF(CB24="","",CB24*$E24) | CC24: =CB24+BZ24 -> 1 | CD24: =IF(CE24="","",CE24*$E24) | CF24: =CE24+CC24 -> 1 | CG24: =IF(CH24="","",CH24*$E24) | CI24: =CH24+CF24 -> 1 | CJ24: =IF(CK24="","",CK24*$E24) | CL24: =CK24+CI24 -> 1 | CM24: =IF(CN24="","",CN24*$E24) | CO24: =CN24+CL24 -> 1 | CP24: =IF(CQ24="","",CQ24*$E24) | CR24: =CQ24+CO24 -> 1 | CS24: =IF(CT24="","",CT24*$E24) | CU24: =CT24+CR24 -> 1 | CV24: =IF(CW24="","",CW24*$E24) | CX24: =CW24+CU24 -> 1 | CY24: =IF(CZ24="","",CZ24*$E24) | DA24: =CZ24+CX24 -> 1 | DB24: =IF(DC24="","",DC24*$E24) | DD24: =DC24+DA24 -> 1 | DE24: =IF(DF24="","",DF24*$E24) | DG24: =DF24+DD24 -> 1 | DH24: =IF(DI24="","",DI24*$E24) | DJ24: =DI24+DG24 -> 1
A25: 3 | B25: 3.1.1.1.3 | C25: PAREDE DE CONTENÇÃO | E25: =VLOOKUP(B25,'[49]PLANILHA ORCAMENTARIA'!A:G,7,0) -> 252879.38 | G25: =IF(H25="","",H25*$E25) | I25: =H25 -> 0 | J25: =IF(K25="","",K25*$E25) | L25: =K25+I25 -> 0 | M25: =IF(N25="","",N25*$E25) | O25: =N25+L25 -> 0 | P25: =IF(Q25="","",Q25*$E25) | R25: =Q25+O25 -> 0 | S25: =IF(T25="","",T25*$E25) -> 252879.38 | T25: 1 | U25: =T25+R25 -> 1 | V25: =IF(W25="","",W25*$E25) | X25: =W25+U25 -> 1 | Y25: =IF(Z25="","",Z25*$E25) | AA25: =Z25+X25 -> 1 | AB25: =IF(AC25="","",AC25*$E25) | AD25: =AC25+AA25 -> 1 | AE25: =IF(AF25="","",AF25*$E25) | AG25: =AF25+AD25 -> 1 | AH25: =IF(AI25="","",AI25*$E25) | AJ25: =AI25+AG25 -> 1 | AK25: =IF(AL25="","",AL25*$E25) | AM25: =AL25+AJ25 -> 1 | AN25: =IF(AO25="","",AO25*$E25) | AP25: =AO25+AM25 -> 1 | AQ25: =IF(AR25="","",AR25*$E25) | AS25: =AR25+AP25 -> 1 | AT25: =IF(AU25="","",AU25*$E25) | AV25: =AU25+AS25 -> 1 | AW25: =IF(AX25="","",AX25*$E25) | AY25: =AX25+AV25 -> 1 | AZ25: =IF(BA25="","",BA25*$E25) | BB25: =BA25+AY25 -> 1 | BC25: =IF(BD25="","",BD25*$E25) | BE25: =BD25+BB25 -> 1 | BF25: =IF(BG25="","",BG25*$E25) | BH25: =BG25+BE25 -> 1 | BI25: =IF(BJ25="","",BJ25*$E25) | BK25: =BJ25+BH25 -> 1 | BL25: =IF(BM25="","",BM25*$E25) | BN25: =BM25+BK25 -> 1 | BO25: =IF(BP25="","",BP25*$E25) | BQ25: =BP25+BN25 -> 1 | BR25: =IF(BS25="","",BS25*$E25) | BT25: =BS25+BQ25 -> 1 | BU25: =IF(BV25="","",BV25*$E25) | BW25: =BV25+BT25 -> 1 | BX25: =IF(BY25="","",BY25*$E25) | BZ25: =BY25+BW25 -> 1 | CA25: =IF(CB25="","",CB25*$E25) | CC25: =CB25+BZ25 -> 1 | CD25: =IF(CE25="","",CE25*$E25) | CF25: =CE25+CC25 -> 1 | CG25: =IF(CH25="","",CH25*$E25) | CI25: =CH25+CF25 -> 1 | CJ25: =IF(CK25="","",CK25*$E25) | CL25: =CK25+CI25 -> 1 | CM25: =IF(CN25="","",CN25*$E25) | CO25: =CN25+CL25 -> 1 | CP25: =IF(CQ25="","",CQ25*$E25) | CR25: =CQ25+CO25 -> 1 | CS25: =IF(CT25="","",CT25*$E25) | CU25: =CT25+CR25 -> 1 | CV25: =IF(CW25="","",CW25*$E25) | CX25: =CW25+CU25 -> 1 | CY25: =IF(CZ25="","",CZ25*$E25) | DA25: =CZ25+CX25 -> 1 | DB25: =IF(DC25="","",DC25*$E25) | DD25: =DC25+DA25 -> 1 | DE25: =IF(DF25="","",DF25*$E25) | DG25: =DF25+DD25 -> 1 | DH25: =IF(DI25="","",DI25*$E25) | DJ25: =DI25+DG25 -> 1
A26: 3 | B26: 3.1.1.2 | C26: ESTACAS HÉLICES | E26: =VLOOKUP(B26,'[49]PLANILHA ORCAMENTARIA'!A:G,7,0) -> 612872.71 | G26: =IF(H26="","",H26*E26) | J26: =IF(K26="","",K26*H26) | M26: =IF(N26="","",N26*K26) | P26: =IF(Q26="","",Q26*N26) | S26: =IF(T26="","",T26*Q26) | V26: =IF(W26="","",W26*T26) | Y26: =IF(Z26="","",Z26*W26) | AB26: =IF(AC26="","",AC26*Z26) | AE26: =IF(AF26="","",AF26*AC26) | AH26: =IF(AI26="","",AI26*AF26) | AK26: =IF(AL26="","",AL26*AI26) | AN26: =IF(AO26="","",AO26*AL26) | AQ26: =IF(AR26="","",AR26*AO26) | AT26: =IF(AU26="","",AU26*AR26) | AW26: =IF(AX26="","",AX26*AU26) | AZ26: =IF(BA26="","",BA26*AX26) | BC26: =IF(BD26="","",BD26*BA26) | BF26: =IF(BG26="","",BG26*BD26) | BI26: =IF(BJ26="","",BJ26*BG26) | BL26: =IF(BM26="","",BM26*BJ26) | BO26: =IF(BP26="","",BP26*BM26) | BR26: =IF(BS26="","",BS26*BP26) | BU26: =IF(BV26="","",BV26*BS26) | BX26: =IF(BY26="","",BY26*BV26) | CA26: =IF(CB26="","",CB26*BY26) | CD26: =IF(CE26="","",CE26*CB26) | CG26: =IF(CH26="","",CH26*CE26) | CJ26: =IF(CK26="","",CK26*CH26) | CM26: =IF(CN26="","",CN26*CK26) | CP26: =IF(CQ26="","",CQ26*CN26) | CS26: =IF(CT26="","",CT26*CQ26) | CV26: =IF(CW26="","",CW26*CT26) | CY26: =IF(CZ26="","",CZ26*CW26) | DB26: =IF(DC26="","",DC26*CZ26) | DE26: =IF(DF26="","",DF26*DC26) | DH26: =IF(DI26="","",DI26*DF26)
A27: 3 | B27: 3.1.1.2.1 | C27: SETOR 1 - ESTACA HÉLICES | E27: =VLOOKUP(B27,'[49]PLANILHA ORCAMENTARIA'!A:G,7,0) -> 140375.28 | G27: =IF(H27="","",H27*$E27) | I27: =H27 -> 0 | J27: =IF(K27="","",K27*$E27) | L27: =K27+I27 -> 0 | M27: =IF(N27="","",N27*$E27) | O27: =N27+L27 -> 0 | P27: =IF(Q27="","",Q27*$E27) -> 140375.28 | Q27: 1 | R27: =Q27+O27 -> 1 | S27: =IF(T27="","",T27*$E27) | U27: =T27+R27 -> 1 | V27: =IF(W27="","",W27*$E27) | X27: =W27+U27 -> 1 | Y27: =IF(Z27="","",Z27*$E27) | AA27: =Z27+X27 -> 1 | AB27: =IF(AC27="","",AC27*$E27) | AD27: =AC27+AA27 -> 1 | AE27: =IF(AF27="","",AF27*$E27) | AG27: =AF27+AD27 -> 1 | AH27: =IF(AI27="","",AI27*$E27) | AJ27: =AI27+AG27 -> 1 | AK27: =IF(AL27="","",AL27*$E27) | AM27: =AL27+AJ27 -> 1 | AN27: =IF(AO27="","",AO27*$E27) | AP27: =AO27+AM27 -> 1 | AQ27: =IF(AR27="","",AR27*$E27) | AS27: =AR27+AP27 -> 1 | AT27: =IF(AU27="","",AU27*$E27) | AV27: =AU27+AS27 -> 1 | AW27: =IF(AX27="","",AX27*$E27) | AY27: =AX27+AV27 -> 1 | AZ27: =IF(BA27="","",BA27*$E27) | BB27: =BA27+AY27 -> 1 | BC27: =IF(BD27="","",BD27*$E27) | BE27: =BD27+BB27 -> 1 | BF27: =IF(BG27="","",BG27*$E27) | BH27: =BG27+BE27 -> 1 | BI27: =IF(BJ27="","",BJ27*$E27) | BK27: =BJ27+BH27 -> 1 | BL27: =IF(BM27="","",BM27*$E27) | BN27: =BM27+BK27 -> 1 | BO27: =IF(BP27="","",BP27*$E27) | BQ27: =BP27+BN27 -> 1 | BR27: =IF(BS27="","",BS27*$E27) | BT27: =BS27+BQ27 -> 1 | BU27: =IF(BV27="","",BV27*$E27) | BW27: =BV27+BT27 -> 1 | BX27: =IF(BY27="","",BY27*$E27) | BZ27: =BY27+BW27 -> 1 | CA27: =IF(CB27="","",CB27*$E27) | CC27: =CB27+BZ27 -> 1 | CD27: =IF(CE27="","",CE27*$E27) | CF27: =CE27+CC27 -> 1 | CG27: =IF(CH27="","",CH27*$E27) | CI27: =CH27+CF27 -> 1 | CJ27: =IF(CK27="","",CK27*$E27) | CL27: =CK27+CI27 -> 1 | CM27: =IF(CN27="","",CN27*$E27) | CO27: =CN27+CL27 -> 1 | CP27: =IF(CQ27="","",CQ27*$E27) | CR27: =CQ27+CO27 -> 1 | CS27: =IF(CT27="","",CT27*$E27) | CU27: =CT27+CR27 -> 1 | CV27: =IF(CW27="","",CW27*$E27) | CX27: =CW27+CU27 -> 1 | CY27: =IF(CZ27="","",CZ27*$E27) | DA27: =CZ27+CX27 -> 1 | DB27: =IF(DC27="","",DC27*$E27) | DD27: =DC27+DA27 -> 1 | DE27: =IF(DF27="","",DF27*$E27) | DG27: =DF27+DD27 -> 1 | DH27: =IF(DI27="","",DI27*$E27) | DJ27: =DI27+DG27 -> 1
A28: 3 | B28: 3.1.1.2.2 | C28: SETOR 2 - ESTACA HÉLICES | E28: =VLOOKUP(B28,'[49]PLANILHA ORCAMENTARIA'!A:G,7,0) -> 159484.82 | G28: =IF(H28="","",H28*$E28) | I28: =H28 -> 0 | J28: =IF(K28="","",K28*$E28) | L28: =K28+I28 -> 0 | M28: =IF(N28="","",N28*$E28) | O28: =N28+L28 -> 0 | P28: =IF(Q28="","",Q28*$E28) | R28: =Q28+O28 -> 0 | S28: =IF(T28="","",T28*$E28) -> 159484.82 | T28: 1 | U28: =T28+R28 -> 1 | V28: =IF(W28="","",W28*$E28) | X28: =W28+U28 -> 1 | Y28: =IF(Z28="","",Z28*$E28) | AA28: =Z28+X28 -> 1 | AB28: =IF(AC28="","",AC28*$E28) | AD28: =AC28+AA28 -> 1 | AE28: =IF(AF28="","",AF28*$E28) | AG28: =AF28+AD28 -> 1 | AH28: =IF(AI28="","",AI28*$E28) | AJ28: =AI28+AG28 -> 1 | AK28: =IF(AL28="","",AL28*$E28) | AM28: =AL28+AJ28 -> 1 | AN28: =IF(AO28="","",AO28*$E28) | AP28: =AO28+AM28 -> 1 | AQ28: =IF(AR28="","",AR28*$E28) | AS28: =AR28+AP28 -> 1 | AT28: =IF(AU28="","",AU28*$E28) | AV28: =AU28+AS28 -> 1 | AW28: =IF(AX28="","",AX28*$E28) | AY28: =AX28+AV28 -> 1 | AZ28: =IF(BA28="","",BA28*$E28) | BB28: =BA28+AY28 -> 1 | BC28: =IF(BD28="","",BD28*$E28) | BE28: =BD28+BB28 -> 1 | BF28: =IF(BG28="","",BG28*$E28) | BH28: =BG28+BE28 -> 1 | BI28: =IF(BJ28="","",BJ28*$E28) | BK28: =BJ28+BH28 -> 1 | BL28: =IF(BM28="","",BM28*$E28) | BN28: =BM28+BK28 -> 1 | BO28: =IF(BP28="","",BP28*$E28) | BQ28: =BP28+BN28 -> 1 | BR28: =IF(BS28="","",BS28*$E28) | BT28: =BS28+BQ28 -> 1 | BU28: =IF(BV28="","",BV28*$E28) | BW28: =BV28+BT28 -> 1 | BX28: =IF(BY28="","",BY28*$E28) | BZ28: =BY28+BW28 -> 1 | CA28: =IF(CB28="","",CB28*$E28) | CC28: =CB28+BZ28 -> 1 | CD28: =IF(CE28="","",CE28*$E28) | CF28: =CE28+CC28 -> 1 | CG28: =IF(CH28="","",CH28*$E28) | CI28: =CH28+CF28 -> 1 | CJ28: =IF(CK28="","",CK28*$E28) | CL28: =CK28+CI28 -> 1 | CM28: =IF(CN28="","",CN28*$E28) | CO28: =CN28+CL28 -> 1 | CP28: =IF(CQ28="","",CQ28*$E28) | CR28: =CQ28+CO28 -> 1 | CS28: =IF(CT28="","",CT28*$E28) | CU28: =CT28+CR28 -> 1 | CV28: =IF(CW28="","",CW28*$E28) | CX28: =CW28+CU28 -> 1 | CY28: =IF(CZ28="","",CZ28*$E28) | DA28: =CZ28+CX28 -> 1 | DB28: =IF(DC28="","",DC28*$E28) | DD28: =DC28+DA28 -> 1 | DE28: =IF(DF28="","",DF28*$E28) | DG28: =DF28+DD28 -> 1 | DH28: =IF(DI28="","",DI28*$E28) | DJ28: =DI28+DG28 -> 1
A29: 3 | B29: 3.1.1.2.3 | C29: SETOR 3 - ESTACA HÉLICES | E29: =VLOOKUP(B29,'[49]PLANILHA ORCAMENTARIA'!A:G,7,0) -> 313012.61 | G29: =IF(H29="","",H29*$E29) | I29: =H29 -> 0 | J29: =IF(K29="","",K29*$E29) | L29: =K29+I29 -> 0 | M29: =IF(N29="","",N29*$E29) | O29: =N29+L29 -> 0 | P29: =IF(Q29="","",Q29*$E29) | R29: =Q29+O29 -> 0 | S29: =IF(T29="","",T29*$E29) -> 313012.61 | T29: 1 | U29: =T29+R29 -> 1 | V29: =IF(W29="","",W29*$E29) | X29: =W29+U29 -> 1 | Y29: =IF(Z29="","",Z29*$E29) | AA29: =Z29+X29 -> 1 | AB29: =IF(AC29="","",AC29*$E29) | AD29: =AC29+AA29 -> 1 | AE29: =IF(AF29="","",AF29*$E29) | AG29: =AF29+AD29 -> 1 | AH29: =IF(AI29="","",AI29*$E29) | AJ29: =AI29+AG29 -> 1 | AK29: =IF(AL29="","",AL29*$E29) | AM29: =AL29+AJ29 -> 1 | AN29: =IF(AO29="","",AO29*$E29) | AP29: =AO29+AM29 -> 1 | AQ29: =IF(AR29="","",AR29*$E29) | AS29: =AR29+AP29 -> 1 | AT29: =IF(AU29="","",AU29*$E29) | AV29: =AU29+AS29 -> 1 | AW29: =IF(AX29="","",AX29*$E29) | AY29: =AX29+AV29 -> 1 | AZ29: =IF(BA29="","",BA29*$E29) | BB29: =BA29+AY29 -> 1 | BC29: =IF(BD29="","",BD29*$E29) | BE29: =BD29+BB29 -> 1 | BF29: =IF(BG29="","",BG29*$E29) | BH29: =BG29+BE29 -> 1 | BI29: =IF(BJ29="","",BJ29*$E29) | BK29: =BJ29+BH29 -> 1 | BL29: =IF(BM29="","",BM29*$E29) | BN29: =BM29+BK29 -> 1 | BO29: =IF(BP29="","",BP29*$E29) | BQ29: =BP29+BN29 -> 1 | BR29: =IF(BS29="","",BS29*$E29) | BT29: =BS29+BQ29 -> 1 | BU29: =IF(BV29="","",BV29*$E29) | BW29: =BV29+BT29 -> 1 | BX29: =IF(BY29="","",BY29*$E29) | BZ29: =BY29+BW29 -> 1 | CA29: =IF(CB29="","",CB29*$E29) | CC29: =CB29+BZ29 -> 1 | CD29: =IF(CE29="","",CE29*$E29) | CF29: =CE29+CC29 -> 1 | CG29: =IF(CH29="","",CH29*$E29) | CI29: =CH29+CF29 -> 1 | CJ29: =IF(CK29="","",CK29*$E29) | CL29: =CK29+CI29 -> 1 | CM29: =IF(CN29="","",CN29*$E29) | CO29: =CN29+CL29 -> 1 | CP29: =IF(CQ29="","",CQ29*$E29) | CR29: =CQ29+CO29 -> 1 | CS29: =IF(CT29="","",CT29*$E29) | CU29: =CT29+CR29 -> 1 | CV29: =IF(CW29="","",CW29*$E29) | CX29: =CW29+CU29 -> 1 | CY29: =IF(CZ29="","",CZ29*$E29) | DA29: =CZ29+CX29 -> 1 | DB29: =IF(DC29="","",DC29*$E29) | DD29: =DC29+DA29 -> 1 | DE29: =IF(DF29="","",DF29*$E29) | DG29: =DF29+DD29 -> 1 | DH29: =IF(DI29="","",DI29*$E29) | DJ29: =DI29+DG29 -> 1
A30: 3 | B30: 3.1.1.3 | C30: BLOCOS DE FUNDAÇÃO | E30: =VLOOKUP(B30,'[49]PLANILHA ORCAMENTARIA'!A:G,7,0) -> 323614.08 | G30: =IF(H30="","",H30*E30) | J30: =IF(K30="","",K30*H30) | M30: =IF(N30="","",N30*K30) | P30: =IF(Q30="","",Q30*N30) | S30: =IF(T30="","",T30*Q30) | V30: =IF(W30="","",W30*T30) | Y30: =IF(Z30="","",Z30*W30) | AB30: =IF(AC30="","",AC30*Z30) | AE30: =IF(AF30="","",AF30*AC30) | AH30: =IF(AI30="","",AI30*AF30) | AK30: =IF(AL30="","",AL30*AI30) | AN30: =IF(AO30="","",AO30*AL30) | AQ30: =IF(AR30="","",AR30*AO30) | AT30: =IF(AU30="","",AU30*AR30) | AW30: =IF(AX30="","",AX30*AU30) | AZ30: =IF(BA30="","",BA30*AX30) | BC30: =IF(BD30="","",BD30*BA30) | BF30: =IF(BG30="","",BG30*BD30) | BI30: =IF(BJ30="","",BJ30*BG30) | BL30: =IF(BM30="","",BM30*BJ30) | BO30: =IF(BP30="","",BP30*BM30) | BR30: =IF(BS30="","",BS30*BP30) | BU30: =IF(BV30="","",BV30*BS30) | BX30: =IF(BY30="","",BY30*BV30) | CA30: =IF(CB30="","",CB30*BY30) | CD30: =IF(CE30="","",CE30*CB30) | CG30: =IF(CH30="","",CH30*CE30) | CJ30: =IF(CK30="","",CK30*CH30) | CM30: =IF(CN30="","",CN30*CK30) | CP30: =IF(CQ30="","",CQ30*CN30) | CS30: =IF(CT30="","",CT30*CQ30) | CV30: =IF(CW30="","",CW30*CT30) | CY30: =IF(CZ30="","",CZ30*CW30) | DB30: =IF(DC30="","",DC30*CZ30) | DE30: =IF(DF30="","",DF30*DC30) | DH30: =IF(DI30="","",DI30*DF30)
A31: 3 | B31: 3.1.1.3.1 | C31: SETOR 1 - BLOCO DE FUNDAÇÃO | E31: =VLOOKUP(B31,'[49]PLANILHA ORCAMENTARIA'!A:G,7,0) -> 78165.999 | G31: =IF(H31="","",H31*$E31) | I31: =H31 -> 0 | J31: =IF(K31="","",K31*$E31) | L31: =K31+I31 -> 0 | M31: =IF(N31="","",N31*$E31) | O31: =N31+L31 -> 0 | P31: =IF(Q31="","",Q31*$E31) | R31: =Q31+O31 -> 0 | S31: =IF(T31="","",T31*$E31) -> 78165.999 | T31: 1 | U31: =T31+R31 -> 1 | V31: =IF(W31="","",W31*$E31) | X31: =W31+U31 -> 1 | Y31: =IF(Z31="","",Z31*$E31) | AA31: =Z31+X31 -> 1 | AB31: =IF(AC31="","",AC31*$E31) | AD31: =AC31+AA31 -> 1 | AE31: =IF(AF31="","",AF31*$E31) | AG31: =AF31+AD31 -> 1 | AH31: =IF(AI31="","",AI31*$E31) | AJ31: =AI31+AG31 -> 1 | AK31: =IF(AL31="","",AL31*$E31) | AM31: =AL31+AJ31 -> 1 | AN31: =IF(AO31="","",AO31*$E31) | AP31: =AO31+AM31 -> 1 | AQ31: =IF(AR31="","",AR31*$E31) | AS31: =AR31+AP31 -> 1 | AT31: =IF(AU31="","",AU31*$E31) | AV31: =AU31+AS31 -> 1 | AW31: =IF(AX31="","",AX31*$E31) | AY31: =AX31+AV31 -> 1 | AZ31: =IF(BA31="","",BA31*$E31) | BB31: =BA31+AY31 -> 1 | BC31: =IF(BD31="","",BD31*$E31) | BE31: =BD31+BB31 -> 1 | BF31: =IF(BG31="","",BG31*$E31) | BH31: =BG31+BE31 -> 1 | BI31: =IF(BJ31="","",BJ31*$E31) | BK31: =BJ31+BH31 -> 1 | BL31: =IF(BM31="","",BM31*$E31) | BN31: =BM31+BK31 -> 1 | BO31: =IF(BP31="","",BP31*$E31) | BQ31: =BP31+BN31 -> 1 | BR31: =IF(BS31="","",BS31*$E31) | BT31: =BS31+BQ31 -> 1 | BU31: =IF(BV31="","",BV31*$E31) | BW31: =BV31+BT31 -> 1 | BX31: =IF(BY31="","",BY31*$E31) | BZ31: =BY31+BW31 -> 1 | CA31: =IF(CB31="","",CB31*$E31) | CC31: =CB31+BZ31 -> 1 | CD31: =IF(CE31="","",CE31*$E31) | CF31: =CE31+CC31 -> 1 | CG31: =IF(CH31="","",CH31*$E31) | CI31: =CH31+CF31 -> 1 | CJ31: =IF(CK31="","",CK31*$E31) | CL31: =CK31+CI31 -> 1 | CM31: =IF(CN31="","",CN31*$E31) | CO31: =CN31+CL31 -> 1 | CP31: =IF(CQ31="","",CQ31*$E31) | CR31: =CQ31+CO31 -> 1 | CS31: =IF(CT31="","",CT31*$E31) | CU31: =CT31+CR31 -> 1 | CV31: =IF(CW31="","",CW31*$E31) | CX31: =CW31+CU31 -> 1 | CY31: =IF(CZ31="","",CZ31*$E31) | DA31: =CZ31+CX31 -> 1 | DB31: =IF(DC31="","",DC31*$E31) | DD31: =DC31+DA31 -> 1 | DE31: =IF(DF31="","",DF31*$E31) | DG31: =DF31+DD31 -> 1 | DH31: =IF(DI31="","",DI31*$E31) | DJ31: =DI31+DG31 -> 1
